Workbook
Name Slicer_Date: #N/A
Name Slicer_Date1: #N/A
Name Slicer_Party: #N/A
Name Slicer_Party_Name: #N/A
Name Slicer_Party_Name1: #N/A
Name Slicer_Party_Name2: #N/A
Name Slicer_Person: #N/A
Name Slicer_Shipment_Number: #N/A

Sheet Billing
B1: Party Name | C1: Tiyaar | D1: Rate | E1: Total | G1: Billing
B2: =B49 -> BSC | C2: =SUMIFS(ledger!G:G, ledger!B:B, B2, ledger!E:E, "<>*RD*") / 1.0936 -> 232352.78 | D2: 10 | E2: =(SUMIFS(ledger!G:G, ledger!B:B, B2, ledger!E:E, "<>*RD*",ledger!D:D, "Silky") / 1.0936)*12 + (SUMIFS(ledger!G:G, ledger!B:B, B2, ledger!E:E, "<>*RD*",ledger!D:D, "Chamki") / 1.0936)*10 -> 2524052.7 | Q2: Billing Total
B3: =B50 -> Ejaz Sahab | C3: =SUMIFS(ledger!G:G, ledger!B:B, B3, ledger!E:E, "<>*RD*") / 1.0936 -> 105662.95 | D3: 10 | E3: =(SUMIFS(ledger!G:G, ledger!B:B, B3, ledger!E:E, "<>*RD*",ledger!D:D, "Silky") / 1.0936)*12 + (SUMIFS(ledger!G:G, ledger!B:B, B3, ledger!E:E, "<>*RD*",ledger!D:D, "Chamki") / 1.0936)*10 -> 1267955.4
B4: =B51 -> Arshad | C4: =SUMIFS(ledger!G:G, ledger!B:B, B4, ledger!E:E, "<>*RD*") / 1.0936 -> 193527.8 | D4: 10 | E4: =(SUMIFS(ledger!G:G, ledger!B:B, B4, ledger!E:E, "<>*RD*",ledger!D:D, "Silky") / 1.0936)*12 + (SUMIFS(ledger!G:G, ledger!B:B, B4, ledger!E:E, "<>*RD*",ledger!D:D, "Chamki") / 1.0936)*10 -> 2061914.8 | R4: Gaz | S4: Total Metres | T4: Total Chamki | U4: Total Super Silky | V4: Billing (Chamki/Crinkle) | W4: Billing (Super Chamki) | X4: Billing (Slub) | Y4: Billing (Satin) | Z4: Billing (Black-chamki) | AB4: Adjusted Bill | AC4: Amount Paid | AD4: Balance | AE4: Rate (Chamki) | AF4: Rate (Super Silky)
B5: =B52 -> Shehzad Kamoki | C5: =SUMIFS(ledger!G:G, ledger!B:B, B5, ledger!E:E, "<>*RD*") / 1.0936 -> 0 | D5: 10.5 | E5: =(SUMIFS(ledger!G:G, ledger!B:B, B5, ledger!E:E, "<>*RD*",ledger!D:D, "Silky") / 1.0936)*12 + (SUMIFS(ledger!G:G, ledger!B:B, B5, ledger!E:E, "<>*RD*",ledger!D:D, "Chamki") / 1.0936)*10.5 -> 0 | Q5: {=_xlfn.UNIQUE(Table1[Party Name])} -> BSC | R5: {=_xlfn.BYROW(B49,_xlfn.LAMBDA(_xlpm.party,SUMIFS(ledger!G:G,ledger!B:B,_xlpm.party,ledger!E:E,"<>*RD*")))+_xlfn.IFNA(C84,0)} -> 2459509 | S5: {=_xlfn.BYROW(B49, _xlfn.LAMBDA(_xlpm.party, SUMIFS(ledger!G:G, ledger!B:B, _xlpm.party, ledger!E:E, "<>*RD*") / 1.0936 ))+_xlfn.IFNA(D84,0)} -> 2249002.4 | T5: {=(_xlfn.BYROW(B49,_xlfn.LAMBDA(_xlpm.party,SUMIFS(ledger!G:G,ledger!B:B,_xlpm.party,ledger!E:E,"<>*RD*",ledger!D:D,"Chamki")+SUMIFS(ledger!G:G, ledger!B:B, _xlpm.party, ledger!E:E, "<>*RD*", ledger!D:D, "Crinkle")))/1.0936)+_xlfn.IFNA(E84,0)} -> 2027492.7 | U5: {=(_xlfn.BYROW(B49,_xlfn.LAMBDA(_xlpm.party,SUMIFS(ledger!G:G,ledger!B:B,_xlpm.party,ledger!E:E,"<>*RD*",ledger!D:D,"Silky")))/1.0936)+_xlfn.IFNA(F84,0)} -> 221509.69 | V5: {=(_xlfn.BYROW(B49,_xlfn.LAMBDA(_xlpm.party, (SUMIFS(ledger!J:J,ledger!B:B,_xlpm.party,ledger!E:E,"<>*RD*",ledger!D:D,"Chamki",ledger!C:C,"<>October Closing CF")+ SUMIFS(ledger!J:J,ledger!B:B,_xlpm.party,ledger!E:E,"<>*RD*",ledger!D:D,"Crinkle",ledger!C:C,"<>October Closing CF") )+_xlfn.IFNA(G84,0))))} -> 20274927 | W5: {=_xlfn.BYROW(B49, _xlfn.LAMBDA(_xlpm.party, SUMIFS(ledger!J:J, ledger!B:B, _xlpm.party, ledger!E:E, "<>*RD*", ledger!D:D, "Silky", ledger!C:C, "<>October Closing CF") )) + _xlfn.IFNA(H84, 0)} -> 2791270.1 | X5: {=_xlfn.BYROW(B49, _xlfn.LAMBDA(_xlpm.party, SUMIFS(ledger!J:J, ledger!B:B, _xlpm.party, ledger!E:E, "<>*RD*", ledger!D:D, "Slub", ledger!C:C, "<>October Closing CF") ))+ _xlfn.IFNA(I84, 0)} -> 0 | Y5: {=_xlfn.BYROW(B49, _xlfn.LAMBDA(_xlpm.party, SUMIFS(ledger!J:J, ledger!B:B, _xlpm.party, ledger!E:E, "<>*RD*", ledger!D:D, "Satin", ledger!C:C, "<>October Closing CF") ))+ _xlfn.IFNA(J84, 0)} -> 0 | Z5: {=_xlfn.BYROW(B49, _xlfn.LAMBDA(_xlpm.party, SUMIFS(ledger!J:J, ledger!B:B, _xlpm.party, ledger!E:E, "<>*RD*", ledger!D:D, "Black-Chamki", ledger!C:C, "<>October Closing CF") ))} -> 0 | AA5: {=_xlfn.BYROW(B49, _xlfn.LAMBDA(_xlpm.party, SUMIFS(ledger!J:J, ledger!B:B, _xlpm.party, ledger!E:E, "<>*RD*", ledger!D:D, "Kataan", ledger!C:C, "<>October Closing CF") ))} -> 0 | AB5: =V5+W5+X5+Y5+Z5+AA5 -> 23066197 | AC5: =(SUMIF(Table14[Party],Q5,Table14[Credit]))+_xlfn.IFNA(L84,0) -> 19750734 | AD5: =AB5-AC5 -> 3315463 | AE5: 10 | AF5: 13
B6: =B53 -> Sufi Nawaz Sahab | C6: =SUMIFS(ledger!G:G, ledger!B:B, B6, ledger!E:E, "<>*RD*") / 1.0936 -> 0 | D6: 10 | E6: =((SUMIFS(ledger!G:G, ledger!B:B, B6, ledger!E:E, "<>*RD*",ledger!D:D, "Silky") / 1.0936) *12) + ((SUMIFS(ledger!G:G, ledger!B:B, B6, ledger!E:E, "<>*RD*",ledger!D:D, "Chamki") / 1.0936)* 9) -> 0 | Q6: Ejaz Sahab | R6: {=_xlfn.BYROW(B50,_xlfn.LAMBDA(_xlpm.party,SUMIFS(ledger!G:G,ledger!B:B,_xlpm.party,ledger!E:E,"<>*RD*")))+_xlfn.IFNA(C85,0)} -> 393394 | S6: {=_xlfn.BYROW(B50, _xlfn.LAMBDA(_xlpm.party, SUMIFS(ledger!G:G, ledger!B:B, _xlpm.party, ledger!E:E, "<>*RD*") / 1.0936 ))+_xlfn.IFNA(D85,0)} -> 359723.85 | T6: {=(_xlfn.BYROW(B50,_xlfn.LAMBDA(_xlpm.party,SUMIFS(ledger!G:G,ledger!B:B,_xlpm.party,ledger!E:E,"<>*RD*",ledger!D:D,"Chamki")+SUMIFS(ledger!G:G, ledger!B:B, _xlpm.party, ledger!E:E, "<>*RD*", ledger!D:D, "Crinkle")))/1.0936)+_xlfn.IFNA(E85,0)} -> 148145.57 | U6: {=(_xlfn.BYROW(B50,_xlfn.LAMBDA(_xlpm.party,SUMIFS(ledger!G:G,ledger!B:B,_xlpm.party,ledger!E:E,"<>*RD*",ledger!D:D,"Silky")))/1.0936)+_xlfn.IFNA(F85,0)} -> 211578.27 | V6: {=(_xlfn.BYROW(B50,_xlfn.LAMBDA(_xlpm.party, (SUMIFS(ledger!J:J,ledger!B:B,_xlpm.party,ledger!E:E,"<>*RD*",ledger!D:D,"Chamki",ledger!C:C,"<>October Closing CF")+ SUMIFS(ledger!J:J,ledger!B:B,_xlpm.party,ledger!E:E,"<>*RD*",ledger!D:D,"Crinkle",ledger!C:C,"<>October Closing CF") )+_xlfn.IFNA(G85,0))))} -> 1481455.7 | W6: {=_xlfn.BYROW(B50, _xlfn.LAMBDA(_xlpm.party, SUMIFS(ledger!J:J, ledger!B:B, _xlpm.party, ledger!E:E, "<>*RD*", ledger!D:D, "Silky", ledger!C:C, "<>October Closing CF") )) + _xlfn.IFNA(H85, 0)} -> 2691373.4 | X6: {=_xlfn.BYROW(B50, _xlfn.LAMBDA(_xlpm.party, SUMIFS(ledger!J:J, ledger!B:B, _xlpm.party, ledger!E:E, "<>*RD*", ledger!D:D, "Slub", ledger!C:C, "<>October Closing CF") ))+ _xlfn.IFNA(I85, 0)} -> 0 | Y6: {=_xlfn.BYROW(B50, _xlfn.LAMBDA(_xlpm.party, SUMIFS(ledger!J:J, ledger!B:B, _xlpm.party, ledger!E:E, "<>*RD*", ledger!D:D, "Satin", ledger!C:C, "<>October Closing CF") ))+ _xlfn.IFNA(J85, 0)} -> 0 | Z6: {=_xlfn.BYROW(B50, _xlfn.LAMBDA(_xlpm.party, SUMIFS(ledger!J:J, ledger!B:B, _xlpm.party, ledger!E:E, "<>*RD*", ledger!D:D, "Black-Chamki", ledger!C:C, "<>October Closing CF") ))} -> 0 | AA6: {=_xlfn.BYROW(B50, _xlfn.LAMBDA(_xlpm.party, SUMIFS(ledger!J:J, ledger!B:B, _xlpm.party, ledger!E:E, "<>*RD*", ledger!D:D, "Kataan", ledger!C:C, "<>October Closing CF") ))} -> 0 | AB6: =V6+W6+X6+Y6+Z6+AA6 -> 4172829.2 | AC6: =(SUMIF(Table14[Party],Q6,Table14[Credit]))+_xlfn.IFNA(L85,0) -> 3663904 | AD6: =AB6-AC6 -> 508925.19 | AE6: 10 | AF6: 13
B7: =B54 -> Sajad Khan | C7: =SUMIFS(ledger!G:G, ledger!B:B, B7, ledger!E:E, "<>*RD*") / 1.0936 -> 172007.13 | D7: 10 | E7: {=(SUMIFS(ledger!G:G, ledger!B:B, B7, ledger!E:E, "<>*RD*",ledger!D:D, "Silky") / 1.0936)*12 + (SUMIFS(ledger!G:G, ledger!B:B, B7, ledger!E:E, "<>*RD*",ledger!D:D, "Chamki") / 1.0936)*10 +(SUMIFS(ledger!G:G, ledger!B:B, party, ledger!E:E, "<>*RD*", ledger!D:D, "Crinkle")/ 1.0936)*10} -> 1720071.3 | Q7: Arshad | R7: {=_xlfn.BYROW(B51,_xlfn.LAMBDA(_xlpm.party,SUMIFS(ledger!G:G,ledger!B:B,_xlpm.party,ledger!E:E,"<>*RD*")))+_xlfn.IFNA(C86,0)} -> 657148 | S7: {=_xlfn.BYROW(B51, _xlfn.LAMBDA(_xlpm.party, SUMIFS(ledger!G:G, ledger!B:B, _xlpm.party, ledger!E:E, "<>*RD*") / 1.0936 ))+_xlfn.IFNA(D86,0)} -> 600903.44 | T7: {=(_xlfn.BYROW(B51,_xlfn.LAMBDA(_xlpm.party,SUMIFS(ledger!G:G,ledger!B:B,_xlpm.party,ledger!E:E,"<>*RD*",ledger!D:D,"Chamki")+SUMIFS(ledger!G:G, ledger!B:B, _xlpm.party, ledger!E:E, "<>*RD*", ledger!D:D, "Crinkle")))/1.0936)+_xlfn.IFNA(E86,0)} -> 522790.78 | U7: {=(_xlfn.BYROW(B51,_xlfn.LAMBDA(_xlpm.party,SUMIFS(ledger!G:G,ledger!B:B,_xlpm.party,ledger!E:E,"<>*RD*",ledger!D:D,"Silky")))/1.0936)+_xlfn.IFNA(F86,0)} -> 78112.655 | V7: {=(_xlfn.BYROW(B51,_xlfn.LAMBDA(_xlpm.party, (SUMIFS(ledger!J:J,ledger!B:B,_xlpm.party,ledger!E:E,"<>*RD*",ledger!D:D,"Chamki",ledger!C:C,"<>October Closing CF")+ SUMIFS(ledger!J:J,ledger!B:B,_xlpm.party,ledger!E:E,"<>*RD*",ledger!D:D,"Crinkle",ledger!C:C,"<>October Closing CF") )+_xlfn.IFNA(G86,0))))} -> 5227907.8 | W7: {=_xlfn.BYROW(B51, _xlfn.LAMBDA(_xlpm.party, SUMIFS(ledger!J:J, ledger!B:B, _xlpm.party, ledger!E:E, "<>*RD*", ledger!D:D, "Silky", ledger!C:C, "<>October Closing CF") )) + _xlfn.IFNA(H86, 0)} -> 1000670.3 | X7: {=_xlfn.BYROW(B51, _xlfn.LAMBDA(_xlpm.party, SUMIFS(ledger!J:J, ledger!B:B, _xlpm.party, ledger!E:E, "<>*RD*", ledger!D:D, "Slub", ledger!C:C, "<>October Closing CF") ))+ _xlfn.IFNA(I86, 0)} -> 0 | Y7: {=_xlfn.BYROW(B51, _xlfn.LAMBDA(_xlpm.party, SUMIFS(ledger!J:J, ledger!B:B, _xlpm.party, ledger!E:E, "<>*RD*", ledger!D:D, "Satin", ledger!C:C, "<>October Closing CF") ))+ _xlfn.IFNA(J86, 0)} -> 0 | Z7: {=_xlfn.BYROW(B51, _xlfn.LAMBDA(_xlpm.party, SUMIFS(ledger!J:J, ledger!B:B, _xlpm.party, ledger!E:E, "<>*RD*", ledger!D:D, "Black-Chamki", ledger!C:C, "<>October Closing CF") ))} -> 0 | AA7: {=_xlfn.BYROW(B51, _xlfn.LAMBDA(_xlpm.party, SUMIFS(ledger!J:J, ledger!B:B, _xlpm.party, ledger!E:E, "<>*RD*", ledger!D:D, "Kataan", ledger!C:C, "<>October Closing CF") ))} -> 0 | AB7: =V7+W7+X7+Y7+Z7+AA7 -> 6228578.1 | AC7: =(SUMIF(Table14[Party],Q7,Table14[Credit]))+_xlfn.IFNA(L86,0) -> 5802935 | AD7: =AB7-AC7 -> 425643.09 | AE7: 10 | AF7: 13
B8: =B55 -> Raaz Fabrics | C8: =SUMIFS(ledger!G:G, ledger!B:B, B8, ledger!E:E, "<>*RD*") / 1.0936 -> 47108.632 | D8: 10 | E8: =(SUMIFS(ledger!G:G, ledger!B:B, B8, ledger!E:E, "<>*RD*",ledger!D:D, "Silky") / 1.0936)*12 + (SUMIFS(ledger!G:G, ledger!B:B, B8, ledger!E:E, "<>*RD*",ledger!D:D, "chamki") / 1.0936)*10 +(SUMIFS(ledger!G:G, ledger!B:B, B8, ledger!E:E, "<>*RD*",ledger!D:D, "Crinkle") / 1.0936)*10 -> 471086.32 | Q8: Shehzad Kamoki | R8: {=_xlfn.BYROW(B52,_xlfn.LAMBDA(_xlpm.party,SUMIFS(ledger!G:G,ledger!B:B,_xlpm.party,ledger!E:E,"<>*RD*")))+_xlfn.IFNA(C87,0)} -> 134607 | S8: {=_xlfn.BYROW(B52, _xlfn.LAMBDA(_xlpm.party, SUMIFS(ledger!G:G, ledger!B:B, _xlpm.party, ledger!E:E, "<>*RD*") / 1.0936 ))+_xlfn.IFNA(D87,0)} -> 123086.14 | T8: {=(_xlfn.BYROW(B52,_xlfn.LAMBDA(_xlpm.party,SUMIFS(ledger!G:G,ledger!B:B,_xlpm.party,ledger!E:E,"<>*RD*",ledger!D:D,"Chamki")+SUMIFS(ledger!G:G, ledger!B:B, _xlpm.party, ledger!E:E, "<>*RD*", ledger!D:D, "Crinkle")))/1.0936)+_xlfn.IFNA(E87,0)} -> 123086.14 | U8: {=(_xlfn.BYROW(B52,_xlfn.LAMBDA(_xlpm.party,SUMIFS(ledger!G:G,ledger!B:B,_xlpm.party,ledger!E:E,"<>*RD*",ledger!D:D,"Silky")))/1.0936)+_xlfn.IFNA(F87,0)} -> 0 | V8: {=(_xlfn.BYROW(B52,_xlfn.LAMBDA(_xlpm.party, (SUMIFS(ledger!J:J,ledger!B:B,_xlpm.party,ledger!E:E,"<>*RD*",ledger!D:D,"Chamki",ledger!C:C,"<>October Closing CF")+ SUMIFS(ledger!J:J,ledger!B:B,_xlpm.party,ledger!E:E,"<>*RD*",ledger!D:D,"Crinkle",ledger!C:C,"<>October Closing CF") )+_xlfn.IFNA(G87,0))))} -> 1269270.3 | W8: {=_xlfn.BYROW(B52, _xlfn.LAMBDA(_xlpm.party, SUMIFS(ledger!J:J, ledger!B:B, _xlpm.party, ledger!E:E, "<>*RD*", ledger!D:D, "Silky", ledger!C:C, "<>October Closing CF") )) + _xlfn.IFNA(H87, 0)} -> 0 | X8: {=_xlfn.BYROW(B52, _xlfn.LAMBDA(_xlpm.party, SUMIFS(ledger!J:J, ledger!B:B, _xlpm.party, ledger!E:E, "<>*RD*", ledger!D:D, "Slub", ledger!C:C, "<>October Closing CF") ))+ _xlfn.IFNA(I87, 0)} -> 0 | Y8: {=_xlfn.BYROW(B52, _xlfn.LAMBDA(_xlpm.party, SUMIFS(ledger!J:J, ledger!B:B, _xlpm.party, ledger!E:E, "<>*RD*", ledger!D:D, "Satin", ledger!C:C, "<>October Closing CF") ))+ _xlfn.IFNA(J87, 0)} -> 0 | Z8: {=_xlfn.BYROW(B52, _xlfn.LAMBDA(_xlpm.party, SUMIFS(ledger!J:J, ledger!B:B, _xlpm.party, ledger!E:E, "<>*RD*", ledger!D:D, "Black-Chamki", ledger!C:C, "<>October Closing CF") ))} -> 0 | AA8: {=_xlfn.BYROW(B52, _xlfn.LAMBDA(_xlpm.party, SUMIFS(ledger!J:J, ledger!B:B, _xlpm.party, ledger!E:E, "<>*RD*", ledger!D:D, "Kataan", ledger!C:C, "<>October Closing CF") ))} -> 0 | AB8: =V8+W8+X8+Y8+Z8+AA8 -> 1269270.3 | AC8: =(SUMIF(Table14[Party],Q8,Table14[Credit]))+_xlfn.IFNA(L87,0) -> 1268740 | AD8: =AB8-AC8 -> 530.34404 | AE8: 10.5 | AF8: 13
B9: =B56 -> Azam | C9: =SUMIFS(ledger!G:G, ledger!B:B, B9, ledger!E:E, "<>*RD*") / 1.0936 -> 139682.7 | D9: 10 | E9: =(SUMIFS(ledger!G:G, ledger!B:B, B9, ledger!E:E, "<>*RD*",ledger!D:D, "Silky") / 1.0936)*12 + (SUMIFS(ledger!G:G, ledger!B:B, B9, ledger!E:E, "<>*RD*",ledger!D:D, "Chamki") / 1.0936)*10 -> 1396827 | Q9: Sufi Nawaz Sahab | R9: {=_xlfn.BYROW(B53,_xlfn.LAMBDA(_xlpm.party,SUMIFS(ledger!G:G,ledger!B:B,_xlpm.party,ledger!E:E,"<>*RD*")))+_xlfn.IFNA(C88,0)} -> 1186725 | S9: {=_xlfn.BYROW(B53, _xlfn.LAMBDA(_xlpm.party, SUMIFS(ledger!G:G, ledger!B:B, _xlpm.party, ledger!E:E, "<>*RD*") / 1.0936 ))+_xlfn.IFNA(D88,0)} -> 1085154.5 | T9: {=(_xlfn.BYROW(B53,_xlfn.LAMBDA(_xlpm.party,SUMIFS(ledger!G:G,ledger!B:B,_xlpm.party,ledger!E:E,"<>*RD*",ledger!D:D,"Chamki")+SUMIFS(ledger!G:G, ledger!B:B, _xlpm.party, ledger!E:E, "<>*RD*", ledger!D:D, "Crinkle")))/1.0936)+_xlfn.IFNA(E88,0)} -> 599330.65 | U9: {=(_xlfn.BYROW(B53,_xlfn.LAMBDA(_xlpm.party,SUMIFS(ledger!G:G,ledger!B:B,_xlpm.party,ledger!E:E,"<>*RD*",ledger!D:D,"Silky")))/1.0936)+_xlfn.IFNA(F88,0)} -> 485823.88 | V9: {=(_xlfn.BYROW(B53,_xlfn.LAMBDA(_xlpm.party, (SUMIFS(ledger!J:J,ledger!B:B,_xlpm.party,ledger!E:E,"<>*RD*",ledger!D:D,"Chamki",ledger!C:C,"<>October Closing CF")+ SUMIFS(ledger!J:J,ledger!B:B,_xlpm.party,ledger!E:E,"<>*RD*",ledger!D:D,"Crinkle",ledger!C:C,"<>October Closing CF") )+_xlfn.IFNA(G88,0))))} -> 5408917.9 | W9: {=_xlfn.BYROW(B53, _xlfn.LAMBDA(_xlpm.party, SUMIFS(ledger!J:J, ledger!B:B, _xlpm.party, ledger!E:E, "<>*RD*", ledger!D:D, "Silky", ledger!C:C, "<>October Closing CF") )) + _xlfn.IFNA(H88, 0)} -> 5829886.6 | X9: {=_xlfn.BYROW(B53, _xlfn.LAMBDA(_xlpm.party, SUMIFS(ledger!J:J, ledger!B:B, _xlpm.party, ledger!E:E, "<>*RD*", ledger!D:D, "Slub", ledger!C:C, "<>October Closing CF") ))+ _xlfn.IFNA(I88, 0)} -> 0 | Y9: {=_xlfn.BYROW(B53, _xlfn.LAMBDA(_xlpm.party, SUMIFS(ledger!J:J, ledger!B:B, _xlpm.party, ledger!E:E, "<>*RD*", ledger!D:D, "Satin", ledger!C:C, "<>October Closing CF") ))+ _xlfn.IFNA(J88, 0)} -> 0 | Z9: {=_xlfn.BYROW(B53, _xlfn.LAMBDA(_xlpm.party, SUMIFS(ledger!J:J, ledger!B:B, _xlpm.party, ledger!E:E, "<>*RD*", ledger!D:D, "Black-Chamki", ledger!C:C, "<>October Closing CF") ))} -> 0 | AA9: {=_xlfn.BYROW(B53, _xlfn.LAMBDA(_xlpm.party, SUMIFS(ledger!J:J, ledger!B:B, _xlpm.party, ledger!E:E, "<>*RD*", ledger!D:D, "Kataan", ledger!C:C, "<>October Closing CF") ))} -> 0 | AB9: =V9+W9+X9+Y9+Z9+AA9 -> 11238804 | AC9: =(SUMIF(Table14[Party],Q9,Table14[Credit]))+_xlfn.IFNA(L88,0) -> 10629100 | AD9: =AB9-AC9 -> 609704.47 | AE9: 10 | AF9: 13
B10: =B57 -> Ubaidullah | C10: =SUMIFS(ledger!G:G, ledger!B:B, B10, ledger!E:E, "<>*RD*") / 1.0936 -> 0 | D10: 10 | E10: =(SUMIFS(ledger!G:G, ledger!B:B, B10, ledger!E:E, "<>*RD*",ledger!D:D, "Silky") / 1.0936)*12 + (SUMIFS(ledger!G:G, ledger!B:B, B10, ledger!E:E, "<>*RD*",ledger!D:D, "Chamki") / 1.0936)*10 -> 0 | Q10: Sajad Khan | R10: {=_xlfn.BYROW(B54,_xlfn.LAMBDA(_xlpm.party,SUMIFS(ledger!G:G,ledger!B:B,_xlpm.party,ledger!E:E,"<>*RD*")))+_xlfn.IFNA(C89,0)} -> 792787 | S10: {=_xlfn.BYROW(B54, _xlfn.LAMBDA(_xlpm.party, SUMIFS(ledger!G:G, ledger!B:B, _xlpm.party, ledger!E:E, "<>*RD*") / 1.0936 ))+_xlfn.IFNA(D89,0)} -> 724933.25 | T10: {=(_xlfn.BYROW(B54,_xlfn.LAMBDA(_xlpm.party,SUMIFS(ledger!G:G,ledger!B:B,_xlpm.party,ledger!E:E,"<>*RD*",ledger!D:D,"Chamki")+SUMIFS(ledger!G:G, ledger!B:B, _xlpm.party, ledger!E:E, "<>*RD*", ledger!D:D, "Crinkle")))/1.0936)+_xlfn.IFNA(E89,0)} -> 719444.04 | U10: {=(_xlfn.BYROW(B54,_xlfn.LAMBDA(_xlpm.party,SUMIFS(ledger!G:G,ledger!B:B,_xlpm.party,ledger!E:E,"<>*RD*",ledger!D:D,"Silky")))/1.0936)+_xlfn.IFNA(F89,0)} -> 0 | V10: {=(_xlfn.BYROW(B54,_xlfn.LAMBDA(_xlpm.party, (SUMIFS(ledger!J:J,ledger!B:B,_xlpm.party,ledger!E:E,"<>*RD*",ledger!D:D,"Chamki",ledger!C:C,"<>October Closing CF")+ SUMIFS(ledger!J:J,ledger!B:B,_xlpm.party,ledger!E:E,"<>*RD*",ledger!D:D,"Crinkle",ledger!C:C,"<>October Closing CF") )+_xlfn.IFNA(G89,0))))} -> 7194440.4 | W10: {=_xlfn.BYROW(B54, _xlfn.LAMBDA(_xlpm.party, SUMIFS(ledger!J:J, ledger!B:B, _xlpm.party, ledger!E:E, "<>*RD*", ledger!D:D, "Silky", ledger!C:C, "<>October Closing CF") )) + _xlfn.IFNA(H89, 0)} -> 0 | X10: {=_xlfn.BYROW(B54, _xlfn.LAMBDA(_xlpm.party, SUMIFS(ledger!J:J, ledger!B:B, _xlpm.party, ledger!E:E, "<>*RD*", ledger!D:D, "Slub", ledger!C:C, "<>October Closing CF") ))+ _xlfn.IFNA(I89, 0)} -> 71359.729 | Y10: {=_xlfn.BYROW(B54, _xlfn.LAMBDA(_xlpm.party, SUMIFS(ledger!J:J, ledger!B:B, _xlpm.party, ledger!E:E, "<>*RD*", ledger!D:D, "Satin", ledger!C:C, "<>October Closing CF") ))+ _xlfn.IFNA(J89, 0)} -> 0 | Z10: {=_xlfn.BYROW(B54, _xlfn.LAMBDA(_xlpm.party, SUMIFS(ledger!J:J, ledger!B:B, _xlpm.party, ledger!E:E, "<>*RD*", ledger!D:D, "Black-Chamki", ledger!C:C, "<>October Closing CF") ))} -> 0 | AA10: {=_xlfn.BYROW(B54, _xlfn.LAMBDA(_xlpm.party, SUMIFS(ledger!J:J, ledger!B:B, _xlpm.party, ledger!E:E, "<>*RD*", ledger!D:D, "Kataan", ledger!C:C, "<>October Closing CF") ))} -> 0 | AB10: =V10+W10+X10+Y10+Z10+AA10 -> 7265800.1 | AC10: =(SUMIF(Table14[Party],Q10,Table14[Credit]))+_xlfn.IFNA(L89,0) -> 6897871 | AD10: =AB10-AC10 -> 367929.11 | AE10: 10 | AF10: 13
B11: =B58 -> Ashraf Zia | C11: =SUMIFS(ledger!G:G, ledger!B:B, B11, ledger!E:E, "<>*RD*") / 1.0936 -> 0 | D11: 12 | E11: =(SUMIFS(ledger!G:G, ledger!B:B, B11, ledger!E:E, "<>*RD*",ledger!D:D, "Silky") / 1.0936)*12 + (SUMIFS(ledger!G:G, ledger!B:B, B11, ledger!E:E, "<>*RD*",ledger!D:D, "Chamki") / 1.0936)*10 -> 0 | Q11: Raaz Fabrics | R11: {=_xlfn.BYROW(B55,_xlfn.LAMBDA(_xlpm.party,SUMIFS(ledger!G:G,ledger!B:B,_xlpm.party,ledger!E:E,"<>*RD*")))+_xlfn.IFNA(C90,0)} -> 152434 | S11: {=_xlfn.BYROW(B55, _xlfn.LAMBDA(_xlpm.party, SUMIFS(ledger!G:G, ledger!B:B, _xlpm.party, ledger!E:E, "<>*RD*") / 1.0936 ))+_xlfn.IFNA(D90,0)} -> 139387.34 | T11: {=(_xlfn.BYROW(B55,_xlfn.LAMBDA(_xlpm.party,SUMIFS(ledger!G:G,ledger!B:B,_xlpm.party,ledger!E:E,"<>*RD*",ledger!D:D,"Chamki")+SUMIFS(ledger!G:G, ledger!B:B, _xlpm.party, ledger!E:E, "<>*RD*", ledger!D:D, "Crinkle")))/1.0936)+_xlfn.IFNA(E90,0)} -> 139387.34 | U11: {=(_xlfn.BYROW(B55,_xlfn.LAMBDA(_xlpm.party,SUMIFS(ledger!G:G,ledger!B:B,_xlpm.party,ledger!E:E,"<>*RD*",ledger!D:D,"Silky")))/1.0936)+_xlfn.IFNA(F90,0)} -> 0 | V11: {=(_xlfn.BYROW(B55,_xlfn.LAMBDA(_xlpm.party, (SUMIFS(ledger!J:J,ledger!B:B,_xlpm.party,ledger!E:E,"<>*RD*",ledger!D:D,"Chamki",ledger!C:C,"<>October Closing CF")+ SUMIFS(ledger!J:J,ledger!B:B,_xlpm.party,ledger!E:E,"<>*RD*",ledger!D:D,"Crinkle",ledger!C:C,"<>October Closing CF") )+_xlfn.IFNA(G90,0))))} -> 1393873.4 | W11: {=_xlfn.BYROW(B55, _xlfn.LAMBDA(_xlpm.party, SUMIFS(ledger!J:J, ledger!B:B, _xlpm.party, ledger!E:E, "<>*RD*", ledger!D:D, "Silky", ledger!C:C, "<>October Closing CF") )) + _xlfn.IFNA(H90, 0)} -> 0 | X11: {=_xlfn.BYROW(B55, _xlfn.LAMBDA(_xlpm.party, SUMIFS(ledger!J:J, ledger!B:B, _xlpm.party, ledger!E:E, "<>*RD*", ledger!D:D, "Slub", ledger!C:C, "<>October Closing CF") ))+ _xlfn.IFNA(I90, 0)} -> 0 | Y11: {=_xlfn.BYROW(B55, _xlfn.LAMBDA(_xlpm.party, SUMIFS(ledger!J:J, ledger!B:B, _xlpm.party, ledger!E:E, "<>*RD*", ledger!D:D, "Satin", ledger!C:C, "<>October Closing CF") ))+ _xlfn.IFNA(J90, 0)} -> 0 | Z11: {=_xlfn.BYROW(B55, _xlfn.LAMBDA(_xlpm.party, SUMIFS(ledger!J:J, ledger!B:B, _xlpm.party, ledger!E:E, "<>*RD*", ledger!D:D, "Black-Chamki", ledger!C:C, "<>October Closing CF") ))} -> 0 | AA11: {=_xlfn.BYROW(B55, _xlfn.LAMBDA(_xlpm.party, SUMIFS(ledger!J:J, ledger!B:B, _xlpm.party, ledger!E:E, "<>*RD*", ledger!D:D, "Kataan", ledger!C:C, "<>October Closing CF") ))} -> 0 | AB11: =V11+W11+X11+Y11+Z11+AA11 -> 1393873.4 | AC11: =(SUMIF(Table14[Party],Q11,Table14[Credit]))+_xlfn.IFNA(L90,0) -> 1000000 | AD11: =AB11-AC11 -> 393873.45 | AE11: 10 | AF11: 13
B12: =B59 -> Hafiz Qureshi | C12: =SUMIFS(ledger!G:G, ledger!B:B, B12, ledger!E:E, "<>*RD*") / 1.0936 -> 64305.048 | E12: =(SUMIFS(ledger!G:G, ledger!B:B, B12, ledger!E:E, "<>*RD*",ledger!D:D, "Silky") / 1.0936)*12 + (SUMIFS(ledger!G:G, ledger!B:B, B12, ledger!E:E, "<>*RD*",ledger!D:D, "Chamki") / 1.0936)*10 -> 643050.48 | Q12: Azam | R12: {=_xlfn.BYROW(B56,_xlfn.LAMBDA(_xlpm.party,SUMIFS(ledger!G:G,ledger!B:B,_xlpm.party,ledger!E:E,"<>*RD*")))+_xlfn.IFNA(C91,0)} -> 357257 | S12: {=_xlfn.BYROW(B56, _xlfn.LAMBDA(_xlpm.party, SUMIFS(ledger!G:G, ledger!B:B, _xlpm.party, ledger!E:E, "<>*RD*") / 1.0936 ))+_xlfn.IFNA(D91,0)} -> 326679.77 | T12: {=(_xlfn.BYROW(B56,_xlfn.LAMBDA(_xlpm.party,SUMIFS(ledger!G:G,ledger!B:B,_xlpm.party,ledger!E:E,"<>*RD*",ledger!D:D,"Chamki")+SUMIFS(ledger!G:G, ledger!B:B, _xlpm.party, ledger!E:E, "<>*RD*", ledger!D:D, "Crinkle")))/1.0936)+_xlfn.IFNA(E91,0)} -> 301491.4 | U12: {=(_xlfn.BYROW(B56,_xlfn.LAMBDA(_xlpm.party,SUMIFS(ledger!G:G,ledger!B:B,_xlpm.party,ledger!E:E,"<>*RD*",ledger!D:D,"Silky")))/1.0936)+_xlfn.IFNA(F91,0)} -> 25188.369 | V12: {=(_xlfn.BYROW(B56,_xlfn.LAMBDA(_xlpm.party, (SUMIFS(ledger!J:J,ledger!B:B,_xlpm.party,ledger!E:E,"<>*RD*",ledger!D:D,"Chamki",ledger!C:C,"<>October Closing CF")+ SUMIFS(ledger!J:J,ledger!B:B,_xlpm.party,ledger!E:E,"<>*RD*",ledger!D:D,"Crinkle",ledger!C:C,"<>October Closing CF") )+_xlfn.IFNA(G91,0))))} -> 3014914 | W12: {=_xlfn.BYROW(B56, _xlfn.LAMBDA(_xlpm.party, SUMIFS(ledger!J:J, ledger!B:B, _xlpm.party, ledger!E:E, "<>*RD*", ledger!D:D, "Silky", ledger!C:C, "<>October Closing CF") )) + _xlfn.IFNA(H91, 0)} -> 327448.79 | X12: {=_xlfn.BYROW(B56, _xlfn.LAMBDA(_xlpm.party, SUMIFS(ledger!J:J, ledger!B:B, _xlpm.party, ledger!E:E, "<>*RD*", ledger!D:D, "Slub", ledger!C:C, "<>October Closing CF") ))+ _xlfn.IFNA(I91, 0)} -> 0 | Y12: {=_xlfn.BYROW(B56, _xlfn.LAMBDA(_xlpm.party, SUMIFS(ledger!J:J, ledger!B:B, _xlpm.party, ledger!E:E, "<>*RD*", ledger!D:D, "Satin", ledger!C:C, "<>October Closing CF") ))+ _xlfn.IFNA(J91, 0)} -> 0 | Z12: {=_xlfn.BYROW(B56, _xlfn.LAMBDA(_xlpm.party, SUMIFS(ledger!J:J, ledger!B:B, _xlpm.party, ledger!E:E, "<>*RD*", ledger!D:D, "Black-Chamki", ledger!C:C, "<>October Closing CF") ))} -> 0 | AA12: {=_xlfn.BYROW(B56, _xlfn.LAMBDA(_xlpm.party, SUMIFS(ledger!J:J, ledger!B:B, _xlpm.party, ledger!E:E, "<>*RD*", ledger!D:D, "Kataan", ledger!C:C, "<>October Closing CF") ))} -> 0 | AB12: =V12+W12+X12+Y12+Z12+AA12 -> 3342362.8 | AC12: =(SUMIF(Table14[Party],Q12,Table14[Credit]))+_xlfn.IFNA(L91,0) -> 3322620 | AD12: =AB12-AC12 -> 19742.838 | AE12: 10 | AF12: 13
B13: =B60 -> Badshah Fabrics | C13: =SUMIFS(ledger!G:G, ledger!B:B, B13, ledger!E:E, "<>*RD*") / 1.0936 -> 68178.493 | E13: =(SUMIFS(ledger!G:G, ledger!B:B, B13, ledger!E:E, "<>*RD*",ledger!D:D, "Silky") / 1.0936)*12 + (SUMIFS(ledger!G:G, ledger!B:B, B13, ledger!E:E, "<>*RD*",ledger!D:D, "Chamki") / 1.0936)*10 -> 789903.07 | Q13: Ubaidullah | R13: {=_xlfn.BYROW(B57,_xlfn.LAMBDA(_xlpm.party,SUMIFS(ledger!G:G,ledger!B:B,_xlpm.party,ledger!E:E,"<>*RD*")))+_xlfn.IFNA(C92,0)} -> 66850 | S13: {=_xlfn.BYROW(B57, _xlfn.LAMBDA(_xlpm.party, SUMIFS(ledger!G:G, ledger!B:B, _xlpm.party, ledger!E:E, "<>*RD*") / 1.0936 ))+_xlfn.IFNA(D92,0)} -> 61128.383 | T13: {=(_xlfn.BYROW(B57,_xlfn.LAMBDA(_xlpm.party,SUMIFS(ledger!G:G,ledger!B:B,_xlpm.party,ledger!E:E,"<>*RD*",ledger!D:D,"Chamki")+SUMIFS(ledger!G:G, ledger!B:B, _xlpm.party, ledger!E:E, "<>*RD*", ledger!D:D, "Crinkle")))/1.0936)+_xlfn.IFNA(E92,0)} -> 46132.955 | U13: {=(_xlfn.BYROW(B57,_xlfn.LAMBDA(_xlpm.party,SUMIFS(ledger!G:G,ledger!B:B,_xlpm.party,ledger!E:E,"<>*RD*",ledger!D:D,"Silky")))/1.0936)+_xlfn.IFNA(F92,0)} -> 14995.428 | V13: {=(_xlfn.BYROW(B57,_xlfn.LAMBDA(_xlpm.party, (SUMIFS(ledger!J:J,ledger!B:B,_xlpm.party,ledger!E:E,"<>*RD*",ledger!D:D,"Chamki",ledger!C:C,"<>October Closing CF")+ SUMIFS(ledger!J:J,ledger!B:B,_xlpm.party,ledger!E:E,"<>*RD*",ledger!D:D,"Crinkle",ledger!C:C,"<>October Closing CF") )+_xlfn.IFNA(G92,0))))} -> 461329.55 | W13: {=_xlfn.BYROW(B57, _xlfn.LAMBDA(_xlpm.party, SUMIFS(ledger!J:J, ledger!B:B, _xlpm.party, ledger!E:E, "<>*RD*", ledger!D:D, "Silky", ledger!C:C, "<>October Closing CF") )) + _xlfn.IFNA(H92, 0)} -> 179945.14 | X13: {=_xlfn.BYROW(B57, _xlfn.LAMBDA(_xlpm.party, SUMIFS(ledger!J:J, ledger!B:B, _xlpm.party, ledger!E:E, "<>*RD*", ledger!D:D, "Slub", ledger!C:C, "<>October Closing CF") ))+ _xlfn.IFNA(I92, 0)} -> 0 | Y13: {=_xlfn.BYROW(B57, _xlfn.LAMBDA(_xlpm.party, SUMIFS(ledger!J:J, ledger!B:B, _xlpm.party, ledger!E:E, "<>*RD*", ledger!D:D, "Satin", ledger!C:C, "<>October Closing CF") ))+ _xlfn.IFNA(J92, 0)} -> 0 | Z13: {=_xlfn.BYROW(B57, _xlfn.LAMBDA(_xlpm.party, SUMIFS(ledger!J:J, ledger!B:B, _xlpm.party, ledger!E:E, "<>*RD*", ledger!D:D, "Black-Chamki", ledger!C:C, "<>October Closing CF") ))} -> 0 | AA13: {=_xlfn.BYROW(B57, _xlfn.LAMBDA(_xlpm.party, SUMIFS(ledger!J:J, ledger!B:B, _xlpm.party, ledger!E:E, "<>*RD*", ledger!D:D, "Kataan", ledger!C:C, "<>October Closing CF") ))} -> 0 | AB13: =V13+W13+X13+Y13+Z13+AA13 -> 641274.69 | AC13: =(SUMIF(Table14[Party],Q13,Table14[Credit]))+_xlfn.IFNA(L92,0) -> 640190 | AD13: =AB13-AC13 -> 1084.6891 | AE13: 10 | AF13: 13
B14: =B61 -> Reject | C14: =SUMIFS(ledger!G:G, ledger!B:B, B14, ledger!E:E, "<>*RD*") / 1.0936 -> 0 | E14: =(SUMIFS(ledger!G:G, ledger!B:B, B14, ledger!E:E, "<>*RD*",ledger!D:D, "Silky") / 1.0936)*12 + (SUMIFS(ledger!G:G, ledger!B:B, B14, ledger!E:E, "<>*RD*",ledger!D:D, "Chamki") / 1.0936)*10 -> 0 | Q14: Ashraf Zia | R14: {=_xlfn.BYROW(B58,_xlfn.LAMBDA(_xlpm.party,SUMIFS(ledger!G:G,ledger!B:B,_xlpm.party,ledger!E:E,"<>*RD*")))+_xlfn.IFNA(C93,0)} -> 23305 | S14: {=_xlfn.BYROW(B58, _xlfn.LAMBDA(_xlpm.party, SUMIFS(ledger!G:G, ledger!B:B, _xlpm.party, ledger!E:E, "<>*RD*") / 1.0936 ))+_xlfn.IFNA(D93,0)} -> 21310.351 | T14: {=(_xlfn.BYROW(B58,_xlfn.LAMBDA(_xlpm.party,SUMIFS(ledger!G:G,ledger!B:B,_xlpm.party,ledger!E:E,"<>*RD*",ledger!D:D,"Chamki")+SUMIFS(ledger!G:G, ledger!B:B, _xlpm.party, ledger!E:E, "<>*RD*", ledger!D:D, "Crinkle")))/1.0936)+_xlfn.IFNA(E93,0)} -> 21310.351 | U14: {=(_xlfn.BYROW(B58,_xlfn.LAMBDA(_xlpm.party,SUMIFS(ledger!G:G,ledger!B:B,_xlpm.party,ledger!E:E,"<>*RD*",ledger!D:D,"Silky")))/1.0936)+_xlfn.IFNA(F93,0)} -> 0 | V14: {=(_xlfn.BYROW(B58,_xlfn.LAMBDA(_xlpm.party, (SUMIFS(ledger!J:J,ledger!B:B,_xlpm.party,ledger!E:E,"<>*RD*",ledger!D:D,"Chamki",ledger!C:C,"<>October Closing CF")+ SUMIFS(ledger!J:J,ledger!B:B,_xlpm.party,ledger!E:E,"<>*RD*",ledger!D:D,"Crinkle",ledger!C:C,"<>October Closing CF") )+_xlfn.IFNA(G93,0))))} -> 255724.21 | W14: {=_xlfn.BYROW(B58, _xlfn.LAMBDA(_xlpm.party, SUMIFS(ledger!J:J, ledger!B:B, _xlpm.party, ledger!E:E, "<>*RD*", ledger!D:D, "Silky", ledger!C:C, "<>October Closing CF") )) + _xlfn.IFNA(H93, 0)} -> 0 | X14: {=_xlfn.BYROW(B58, _xlfn.LAMBDA(_xlpm.party, SUMIFS(ledger!J:J, ledger!B:B, _xlpm.party, ledger!E:E, "<>*RD*", ledger!D:D, "Slub", ledger!C:C, "<>October Closing CF") ))+ _xlfn.IFNA(I93, 0)} -> 0 | Y14: {=_xlfn.BYROW(B58, _xlfn.LAMBDA(_xlpm.party, SUMIFS(ledger!J:J, ledger!B:B, _xlpm.party, ledger!E:E, "<>*RD*", ledger!D:D, "Satin", ledger!C:C, "<>October Closing CF") ))+ _xlfn.IFNA(J93, 0)} -> 0 | Z14: {=_xlfn.BYROW(B58, _xlfn.LAMBDA(_xlpm.party, SUMIFS(ledger!J:J, ledger!B:B, _xlpm.party, ledger!E:E, "<>*RD*", ledger!D:D, "Black-Chamki", ledger!C:C, "<>October Closing CF") ))} -> 0 | AA14: {=_xlfn.BYROW(B58, _xlfn.LAMBDA(_xlpm.party, SUMIFS(ledger!J:J, ledger!B:B, _xlpm.party, ledger!E:E, "<>*RD*", ledger!D:D, "Kataan", ledger!C:C, "<>October Closing CF") ))} -> 0 | AB14: =V14+W14+X14+Y14+Z14+AA14 -> 255724.21 | AC14: =(SUMIF(Table14[Party],Q14,Table14[Credit]))+_xlfn.IFNA(L93,0) -> 130000 | AD14: =AB14-AC14 -> 125724.21 | AE14: 12 | AF14: 13
B15: =B62 -> Amjad 7up | C15: =SUMIFS(ledger!G:G, ledger!B:B, B15, ledger!E:E, "<>*RD*") / 1.0936 -> 0 | E15: =(SUMIFS(ledger!G:G, ledger!B:B, B15, ledger!E:E, "<>*RD*",ledger!D:D, "Silky") / 1.0936)*12 + (SUMIFS(ledger!G:G, ledger!B:B, B15, ledger!E:E, "<>*RD*",ledger!D:D, "Chamki") / 1.0936)*10 -> 0 | Q15: Hafiz Qureshi | R15: {=_xlfn.BYROW(B59,_xlfn.LAMBDA(_xlpm.party,SUMIFS(ledger!G:G,ledger!B:B,_xlpm.party,ledger!E:E,"<>*RD*")))+_xlfn.IFNA(C94,0)} -> 202815 | S15: {=_xlfn.BYROW(B59, _xlfn.LAMBDA(_xlpm.party, SUMIFS(ledger!G:G, ledger!B:B, _xlpm.party, ledger!E:E, "<>*RD*") / 1.0936 ))+_xlfn.IFNA(D94,0)} -> 185456.29 | T15: {=(_xlfn.BYROW(B59,_xlfn.LAMBDA(_xlpm.party,SUMIFS(ledger!G:G,ledger!B:B,_xlpm.party,ledger!E:E,"<>*RD*",ledger!D:D,"Chamki")+SUMIFS(ledger!G:G, ledger!B:B, _xlpm.party, ledger!E:E, "<>*RD*", ledger!D:D, "Crinkle")))/1.0936)+_xlfn.IFNA(E94,0)} -> 185456.29 | U15: {=(_xlfn.BYROW(B59,_xlfn.LAMBDA(_xlpm.party,SUMIFS(ledger!G:G,ledger!B:B,_xlpm.party,ledger!E:E,"<>*RD*",ledger!D:D,"Silky")))/1.0936)+_xlfn.IFNA(F94,0)} -> 0 | V15: {=(_xlfn.BYROW(B59,_xlfn.LAMBDA(_xlpm.party, (SUMIFS(ledger!J:J,ledger!B:B,_xlpm.party,ledger!E:E,"<>*RD*",ledger!D:D,"Chamki",ledger!C:C,"<>October Closing CF")+ SUMIFS(ledger!J:J,ledger!B:B,_xlpm.party,ledger!E:E,"<>*RD*",ledger!D:D,"Crinkle",ledger!C:C,"<>October Closing CF") )+_xlfn.IFNA(G94,0))))} -> 1854562.9 | W15: {=_xlfn.BYROW(B59, _xlfn.LAMBDA(_xlpm.party, SUMIFS(ledger!J:J, ledger!B:B, _xlpm.party, ledger!E:E, "<>*RD*", ledger!D:D, "Silky", ledger!C:C, "<>October Closing CF") )) + _xlfn.IFNA(H94, 0)} -> 0 | X15: {=_xlfn.BYROW(B59, _xlfn.LAMBDA(_xlpm.party, SUMIFS(ledger!J:J, ledger!B:B, _xlpm.party, ledger!E:E, "<>*RD*", ledger!D:D, "Slub", ledger!C:C, "<>October Closing CF") ))+ _xlfn.IFNA(I94, 0)} -> 0 | Y15: {=_xlfn.BYROW(B59, _xlfn.LAMBDA(_xlpm.party, SUMIFS(ledger!J:J, ledger!B:B, _xlpm.party, ledger!E:E, "<>*RD*", ledger!D:D, "Satin", ledger!C:C, "<>October Closing CF") ))+ _xlfn.IFNA(J94, 0)} -> 0 | Z15: {=_xlfn.BYROW(B59, _xlfn.LAMBDA(_xlpm.party, SUMIFS(ledger!J:J, ledger!B:B, _xlpm.party, ledger!E:E, "<>*RD*", ledger!D:D, "Black-Chamki", ledger!C:C, "<>October Closing CF") ))} -> 0 | AA15: {=_xlfn.BYROW(B59, _xlfn.LAMBDA(_xlpm.party, SUMIFS(ledger!J:J, ledger!B:B, _xlpm.party, ledger!E:E, "<>*RD*", ledger!D:D, "Kataan", ledger!C:C, "<>October Closing CF") ))} -> 0 | AB15: =V15+W15+X15+Y15+Z15+AA15 -> 1854562.9 | AC15: =(SUMIF(Table14[Party],Q15,Table14[Credit]))+_xlfn.IFNA(L94,0) -> 1805980 | AD15: =AB15-AC15 -> 48582.911 | AE15: 10 | AF15: 13
B16: =B63 -> Hazrat Khan | C16: =SUMIFS(ledger!G:G, ledger!B:B, B16, ledger!E:E, "<>*RD*") / 1.0936 -> 0 | E16: =(SUMIFS(ledger!G:G, ledger!B:B, B16, ledger!E:E, "<>*RD*",ledger!D:D, "Silky") / 1.0936)*12 + (SUMIFS(ledger!G:G, ledger!B:B, B16, ledger!E:E, "<>*RD*",ledger!D:D, "Chamki") / 1.0936)*10 -> 0 | Q16: Badshah Fabrics | R16: {=_xlfn.BYROW(B60,_xlfn.LAMBDA(_xlpm.party,SUMIFS(ledger!G:G,ledger!B:B,_xlpm.party,ledger!E:E,"<>*RD*")))+_xlfn.IFNA(C95,0)} -> 517408 | S16: {=_xlfn.BYROW(B60, _xlfn.LAMBDA(_xlpm.party, SUMIFS(ledger!G:G, ledger!B:B, _xlpm.party, ledger!E:E, "<>*RD*") / 1.0936 ))+_xlfn.IFNA(D95,0)} -> 473123.63 | T16: {=(_xlfn.BYROW(B60,_xlfn.LAMBDA(_xlpm.party,SUMIFS(ledger!G:G,ledger!B:B,_xlpm.party,ledger!E:E,"<>*RD*",ledger!D:D,"Chamki")+SUMIFS(ledger!G:G, ledger!B:B, _xlpm.party, ledger!E:E, "<>*RD*", ledger!D:D, "Crinkle")))/1.0936)+_xlfn.IFNA(E95,0)} -> 355909.84 | U16: {=(_xlfn.BYROW(B60,_xlfn.LAMBDA(_xlpm.party,SUMIFS(ledger!G:G,ledger!B:B,_xlpm.party,ledger!E:E,"<>*RD*",ledger!D:D,"Silky")))/1.0936)+_xlfn.IFNA(F95,0)} -> 117213.79 | V16: {=(_xlfn.BYROW(B60,_xlfn.LAMBDA(_xlpm.party, (SUMIFS(ledger!J:J,ledger!B:B,_xlpm.party,ledger!E:E,"<>*RD*",ledger!D:D,"Chamki",ledger!C:C,"<>October Closing CF")+ SUMIFS(ledger!J:J,ledger!B:B,_xlpm.party,ledger!E:E,"<>*RD*",ledger!D:D,"Crinkle",ledger!C:C,"<>October Closing CF") )+_xlfn.IFNA(G95,0))))} -> 3559098.4 | W16: {=_xlfn.BYROW(B60, _xlfn.LAMBDA(_xlpm.party, SUMIFS(ledger!J:J, ledger!B:B, _xlpm.party, ledger!E:E, "<>*RD*", ledger!D:D, "Silky", ledger!C:C, "<>October Closing CF") )) + _xlfn.IFNA(H95, 0)} -> 1460624.5 | X16: {=_xlfn.BYROW(B60, _xlfn.LAMBDA(_xlpm.party, SUMIFS(ledger!J:J, ledger!B:B, _xlpm.party, ledger!E:E, "<>*RD*", ledger!D:D, "Slub", ledger!C:C, "<>October Closing CF") ))+ _xlfn.IFNA(I95, 0)} -> 0 | Y16: {=_xlfn.BYROW(B60, _xlfn.LAMBDA(_xlpm.party, SUMIFS(ledger!J:J, ledger!B:B, _xlpm.party, ledger!E:E, "<>*RD*", ledger!D:D, "Satin", ledger!C:C, "<>October Closing CF") ))+ _xlfn.IFNA(J95, 0)} -> 0 | Z16: {=_xlfn.BYROW(B60, _xlfn.LAMBDA(_xlpm.party, SUMIFS(ledger!J:J, ledger!B:B, _xlpm.party, ledger!E:E, "<>*RD*", ledger!D:D, "Black-Chamki", ledger!C:C, "<>October Closing CF") ))} -> 0 | AA16: {=_xlfn.BYROW(B60, _xlfn.LAMBDA(_xlpm.party, SUMIFS(ledger!J:J, ledger!B:B, _xlpm.party, ledger!E:E, "<>*RD*", ledger!D:D, "Kataan", ledger!C:C, "<>October Closing CF") ))} -> 0 | AB16: =V16+W16+X16+Y16+Z16+AA16 -> 5019722.9 | AC16: =(SUMIF(Table14[Party],Q16,Table14[Credit]))+_xlfn.IFNA(L95,0) -> 4925761 | AD16: =AB16-AC16 -> 93961.933 | AE16: 10 | AF16: 13
B17: =B64 -> Haseeb Shamsi | C17: =SUMIFS(ledger!G:G, ledger!B:B, B17, ledger!E:E, "<>*RD*") / 1.0936 -> 0 | E17: =(SUMIFS(ledger!G:G, ledger!B:B, B17, ledger!E:E, "<>*RD*",ledger!D:D, "Silky") / 1.0936)*12 + (SUMIFS(ledger!G:G, ledger!B:B, B17, ledger!E:E, "<>*RD*",ledger!D:D, "Chamki") / 1.0936)*10 -> 0 | Q17: Reject | R17: {=_xlfn.BYROW(B61,_xlfn.LAMBDA(_xlpm.party,SUMIFS(ledger!G:G,ledger!B:B,_xlpm.party,ledger!E:E,"<>*RD*")))+_xlfn.IFNA(C96,0)} -> 0 | S17: {=_xlfn.BYROW(B61, _xlfn.LAMBDA(_xlpm.party, SUMIFS(ledger!G:G, ledger!B:B, _xlpm.party, ledger!E:E, "<>*RD*") / 1.0936 ))+_xlfn.IFNA(D96,0)} -> 0 | T17: {=(_xlfn.BYROW(B61,_xlfn.LAMBDA(_xlpm.party,SUMIFS(ledger!G:G,ledger!B:B,_xlpm.party,ledger!E:E,"<>*RD*",ledger!D:D,"Chamki")+SUMIFS(ledger!G:G, ledger!B:B, _xlpm.party, ledger!E:E, "<>*RD*", ledger!D:D, "Crinkle")))/1.0936)+_xlfn.IFNA(E96,0)} -> 0 | U17: {=(_xlfn.BYROW(B61,_xlfn.LAMBDA(_xlpm.party,SUMIFS(ledger!G:G,ledger!B:B,_xlpm.party,ledger!E:E,"<>*RD*",ledger!D:D,"Silky")))/1.0936)+_xlfn.IFNA(F96,0)} -> 0 | V17: {=(_xlfn.BYROW(B61,_xlfn.LAMBDA(_xlpm.party, (SUMIFS(ledger!J:J,ledger!B:B,_xlpm.party,ledger!E:E,"<>*RD*",ledger!D:D,"Chamki",ledger!C:C,"<>October Closing CF")+ SUMIFS(ledger!J:J,ledger!B:B,_xlpm.party,ledger!E:E,"<>*RD*",ledger!D:D,"Crinkle",ledger!C:C,"<>October Closing CF") )+_xlfn.IFNA(G96,0))))} -> 0 | W17: {=_xlfn.BYROW(B61, _xlfn.LAMBDA(_xlpm.party, SUMIFS(ledger!J:J, ledger!B:B, _xlpm.party, ledger!E:E, "<>*RD*", ledger!D:D, "Silky", ledger!C:C, "<>October Closing CF") )) + _xlfn.IFNA(H96, 0)} -> 0 | X17: {=_xlfn.BYROW(B61, _xlfn.LAMBDA(_xlpm.party, SUMIFS(ledger!J:J, ledger!B:B, _xlpm.party, ledger!E:E, "<>*RD*", ledger!D:D, "Slub", ledger!C:C, "<>October Closing CF") ))+ _xlfn.IFNA(I96, 0)} -> 0 | Y17: {=_xlfn.BYROW(B61, _xlfn.LAMBDA(_xlpm.party, SUMIFS(ledger!J:J, ledger!B:B, _xlpm.party, ledger!E:E, "<>*RD*", ledger!D:D, "Satin", ledger!C:C, "<>October Closing CF") ))+ _xlfn.IFNA(J96, 0)} -> 0 | Z17: {=_xlfn.BYROW(B61, _xlfn.LAMBDA(_xlpm.party, SUMIFS(ledger!J:J, ledger!B:B, _xlpm.party, ledger!E:E, "<>*RD*", ledger!D:D, "Black-Chamki", ledger!C:C, "<>October Closing CF") ))} -> 0 | AA17: {=_xlfn.BYROW(B61, _xlfn.LAMBDA(_xlpm.party, SUMIFS(ledger!J:J, ledger!B:B, _xlpm.party, ledger!E:E, "<>*RD*", ledger!D:D, "Kataan", ledger!C:C, "<>October Closing CF") ))} -> 0 | AB17: =V17+W17+X17+Y17+Z17+AA17 -> 0 | AC17: =(SUMIF(Table14[Party],Q17,Table14[Credit]))+_xlfn.IFNA(L96,0) -> 0 | AD17: =AB17-AC17 -> 0 | AE17: 10 | AF17: 13
B18: =B65 -> Faizan | C18: =SUMIFS(ledger!G:G, ledger!B:B, B18, ledger!E:E, "<>*RD*") / 1.0936 -> 198235.19 | E18: =(SUMIFS(ledger!G:G, ledger!B:B, B18, ledger!E:E, "<>*RD*",ledger!D:D, "Silky") / 1.0936)*12 + (SUMIFS(ledger!G:G, ledger!B:B, B18, ledger!E:E, "<>*RD*",ledger!D:D, "Chamki") / 1.0936)*10 -> 2378822.2 | Q18: Amjad 7up | R18: {=_xlfn.BYROW(B62,_xlfn.LAMBDA(_xlpm.party,SUMIFS(ledger!G:G,ledger!B:B,_xlpm.party,ledger!E:E,"<>*RD*")))+_xlfn.IFNA(C97,0)} -> 52914 | S18: {=_xlfn.BYROW(B62, _xlfn.LAMBDA(_xlpm.party, SUMIFS(ledger!G:G, ledger!B:B, _xlpm.party, ledger!E:E, "<>*RD*") / 1.0936 ))+_xlfn.IFNA(D97,0)} -> 48385.15 | T18: {=(_xlfn.BYROW(B62,_xlfn.LAMBDA(_xlpm.party,SUMIFS(ledger!G:G,ledger!B:B,_xlpm.party,ledger!E:E,"<>*RD*",ledger!D:D,"Chamki")+SUMIFS(ledger!G:G, ledger!B:B, _xlpm.party, ledger!E:E, "<>*RD*", ledger!D:D, "Crinkle")))/1.0936)+_xlfn.IFNA(E97,0)} -> 48385.15 | U18: {=(_xlfn.BYROW(B62,_xlfn.LAMBDA(_xlpm.party,SUMIFS(ledger!G:G,ledger!B:B,_xlpm.party,ledger!E:E,"<>*RD*",ledger!D:D,"Silky")))/1.0936)+_xlfn.IFNA(F97,0)} -> 0 | V18: {=(_xlfn.BYROW(B62,_xlfn.LAMBDA(_xlpm.party, (SUMIFS(ledger!J:J,ledger!B:B,_xlpm.party,ledger!E:E,"<>*RD*",ledger!D:D,"Chamki",ledger!C:C,"<>October Closing CF")+ SUMIFS(ledger!J:J,ledger!B:B,_xlpm.party,ledger!E:E,"<>*RD*",ledger!D:D,"Crinkle",ledger!C:C,"<>October Closing CF") )+_xlfn.IFNA(G97,0))))} -> 483851.5 | W18: {=_xlfn.BYROW(B62, _xlfn.LAMBDA(_xlpm.party, SUMIFS(ledger!J:J, ledger!B:B, _xlpm.party, ledger!E:E, "<>*RD*", ledger!D:D, "Silky", ledger!C:C, "<>October Closing CF") )) + _xlfn.IFNA(H97, 0)} -> 0 | X18: {=_xlfn.BYROW(B62, _xlfn.LAMBDA(_xlpm.party, SUMIFS(ledger!J:J, ledger!B:B, _xlpm.party, ledger!E:E, "<>*RD*", ledger!D:D, "Slub", ledger!C:C, "<>October Closing CF") ))+ _xlfn.IFNA(I97, 0)} -> 0 | Y18: {=_xlfn.BYROW(B62, _xlfn.LAMBDA(_xlpm.party, SUMIFS(ledger!J:J, ledger!B:B, _xlpm.party, ledger!E:E, "<>*RD*", ledger!D:D, "Satin", ledger!C:C, "<>October Closing CF") ))+ _xlfn.IFNA(J97, 0)} -> 0 | Z18: {=_xlfn.BYROW(B62, _xlfn.LAMBDA(_xlpm.party, SUMIFS(ledger!J:J, ledger!B:B, _xlpm.party, ledger!E:E, "<>*RD*", ledger!D:D, "Black-Chamki", ledger!C:C, "<>October Closing CF") ))} -> 0 | AA18: {=_xlfn.BYROW(B62, _xlfn.LAMBDA(_xlpm.party, SUMIFS(ledger!J:J, ledger!B:B, _xlpm.party, ledger!E:E, "<>*RD*", ledger!D:D, "Kataan", ledger!C:C, "<>October Closing CF") ))} -> 0 | AB18: =V18+W18+X18+Y18+Z18+AA18 -> 483851.5 | AC18: =(SUMIF(Table14[Party],Q18,Table14[Credit]))+_xlfn.IFNA(L97,0) -> 480000 | AD18: =AB18-AC18 -> 3851.4996 | AE18: 10 | AF18: 13
Q19: Hazrat Khan | R19: {=_xlfn.BYROW(B63,_xlfn.LAMBDA(_xlpm.party,SUMIFS(ledger!G:G,ledger!B:B,_xlpm.party,ledger!E:E,"<>*RD*")))+_xlfn.IFNA(C98,0)} -> 9750 | S19: {=_xlfn.BYROW(B63, _xlfn.LAMBDA(_xlpm.party, SUMIFS(ledger!G:G, ledger!B:B, _xlpm.party, ledger!E:E, "<>*RD*") / 1.0936 ))+_xlfn.IFNA(D98,0)} -> 8915.5084 | T19: {=(_xlfn.BYROW(B63,_xlfn.LAMBDA(_xlpm.party,SUMIFS(ledger!G:G,ledger!B:B,_xlpm.party,ledger!E:E,"<>*RD*",ledger!D:D,"Chamki")+SUMIFS(ledger!G:G, ledger!B:B, _xlpm.party, ledger!E:E, "<>*RD*", ledger!D:D, "Crinkle")))/1.0936)+_xlfn.IFNA(E98,0)} -> 8915.5084 | U19: {=(_xlfn.BYROW(B63,_xlfn.LAMBDA(_xlpm.party,SUMIFS(ledger!G:G,ledger!B:B,_xlpm.party,ledger!E:E,"<>*RD*",ledger!D:D,"Silky")))/1.0936)+_xlfn.IFNA(F98,0)} -> 0 | V19: {=(_xlfn.BYROW(B63,_xlfn.LAMBDA(_xlpm.party, (SUMIFS(ledger!J:J,ledger!B:B,_xlpm.party,ledger!E:E,"<>*RD*",ledger!D:D,"Chamki",ledger!C:C,"<>October Closing CF")+ SUMIFS(ledger!J:J,ledger!B:B,_xlpm.party,ledger!E:E,"<>*RD*",ledger!D:D,"Crinkle",ledger!C:C,"<>October Closing CF") )+_xlfn.IFNA(G98,0))))} -> 89155.084 | W19: {=_xlfn.BYROW(B63, _xlfn.LAMBDA(_xlpm.party, SUMIFS(ledger!J:J, ledger!B:B, _xlpm.party, ledger!E:E, "<>*RD*", ledger!D:D, "Silky", ledger!C:C, "<>October Closing CF") )) + _xlfn.IFNA(H98, 0)} -> 0 | X19: {=_xlfn.BYROW(B63, _xlfn.LAMBDA(_xlpm.party, SUMIFS(ledger!J:J, ledger!B:B, _xlpm.party, ledger!E:E, "<>*RD*", ledger!D:D, "Slub", ledger!C:C, "<>October Closing CF") ))+ _xlfn.IFNA(I98, 0)} -> 0 | Y19: {=_xlfn.BYROW(B63, _xlfn.LAMBDA(_xlpm.party, SUMIFS(ledger!J:J, ledger!B:B, _xlpm.party, ledger!E:E, "<>*RD*", ledger!D:D, "Satin", ledger!C:C, "<>October Closing CF") ))+ _xlfn.IFNA(J98, 0)} -> 0 | Z19: {=_xlfn.BYROW(B63, _xlfn.LAMBDA(_xlpm.party, SUMIFS(ledger!J:J, ledger!B:B, _xlpm.party, ledger!E:E, "<>*RD*", ledger!D:D, "Black-Chamki", ledger!C:C, "<>October Closing CF") ))} -> 0 | AA19: {=_xlfn.BYROW(B63, _xlfn.LAMBDA(_xlpm.party, SUMIFS(ledger!J:J, ledger!B:B, _xlpm.party, ledger!E:E, "<>*RD*", ledger!D:D, "Kataan", ledger!C:C, "<>October Closing CF") ))} -> 0 | AB19: =V19+W19+X19+Y19+Z19+AA19 -> 89155.084 | AC19: =(SUMIF(Table14[Party],Q19,Table14[Credit]))+_xlfn.IFNA(L98,0) -> 95000 | AD19: =AB19-AC19 -> -5844.9159 | AE19: 10 | AF19: 13
Q20: Haseeb Shamsi | R20: {=_xlfn.BYROW(B64,_xlfn.LAMBDA(_xlpm.party,SUMIFS(ledger!G:G,ledger!B:B,_xlpm.party,ledger!E:E,"<>*RD*")))+_xlfn.IFNA(C99,0)} -> 61975 | S20: {=_xlfn.BYROW(B64, _xlfn.LAMBDA(_xlpm.party, SUMIFS(ledger!G:G, ledger!B:B, _xlpm.party, ledger!E:E, "<>*RD*") / 1.0936 ))+_xlfn.IFNA(D99,0)} -> 56670.629 | T20: {=(_xlfn.BYROW(B64,_xlfn.LAMBDA(_xlpm.party,SUMIFS(ledger!G:G,ledger!B:B,_xlpm.party,ledger!E:E,"<>*RD*",ledger!D:D,"Chamki")+SUMIFS(ledger!G:G, ledger!B:B, _xlpm.party, ledger!E:E, "<>*RD*", ledger!D:D, "Crinkle")))/1.0936)+_xlfn.IFNA(E99,0)} -> 47437.82 | U20: {=(_xlfn.BYROW(B64,_xlfn.LAMBDA(_xlpm.party,SUMIFS(ledger!G:G,ledger!B:B,_xlpm.party,ledger!E:E,"<>*RD*",ledger!D:D,"Silky")))/1.0936)+_xlfn.IFNA(F99,0)} -> 9232.8091 | V20: {=(_xlfn.BYROW(B64,_xlfn.LAMBDA(_xlpm.party, (SUMIFS(ledger!J:J,ledger!B:B,_xlpm.party,ledger!E:E,"<>*RD*",ledger!D:D,"Chamki",ledger!C:C,"<>October Closing CF")+ SUMIFS(ledger!J:J,ledger!B:B,_xlpm.party,ledger!E:E,"<>*RD*",ledger!D:D,"Crinkle",ledger!C:C,"<>October Closing CF") )+_xlfn.IFNA(G99,0))))} -> 474378.2 | W20: {=_xlfn.BYROW(B64, _xlfn.LAMBDA(_xlpm.party, SUMIFS(ledger!J:J, ledger!B:B, _xlpm.party, ledger!E:E, "<>*RD*", ledger!D:D, "Silky", ledger!C:C, "<>October Closing CF") )) + _xlfn.IFNA(H99, 0)} -> 120026.52 | X20: {=_xlfn.BYROW(B64, _xlfn.LAMBDA(_xlpm.party, SUMIFS(ledger!J:J, ledger!B:B, _xlpm.party, ledger!E:E, "<>*RD*", ledger!D:D, "Slub", ledger!C:C, "<>October Closing CF") ))+ _xlfn.IFNA(I99, 0)} -> 0 | Y20: {=_xlfn.BYROW(B64, _xlfn.LAMBDA(_xlpm.party, SUMIFS(ledger!J:J, ledger!B:B, _xlpm.party, ledger!E:E, "<>*RD*", ledger!D:D, "Satin", ledger!C:C, "<>October Closing CF") ))+ _xlfn.IFNA(J99, 0)} -> 0 | Z20: {=_xlfn.BYROW(B64, _xlfn.LAMBDA(_xlpm.party, SUMIFS(ledger!J:J, ledger!B:B, _xlpm.party, ledger!E:E, "<>*RD*", ledger!D:D, "Black-Chamki", ledger!C:C, "<>October Closing CF") ))} -> 0 | AA20: {=_xlfn.BYROW(B64, _xlfn.LAMBDA(_xlpm.party, SUMIFS(ledger!J:J, ledger!B:B, _xlpm.party, ledger!E:E, "<>*RD*", ledger!D:D, "Kataan", ledger!C:C, "<>October Closing CF") ))} -> 0 | AB20: =V20+W20+X20+Y20+Z20+AA20 -> 594404.72 | AC20: =(SUMIF(Table14[Party],Q20,Table14[Credit]))+_xlfn.IFNA(L99,0) -> 594405 | AD20: =AB20-AC20 -> -0.28163862 | AE20: 10 | AF20: 13
B21: Total: | C21: =SUM(K49:K78) -> 18025314 | D21: (Real Figure) | Q21: Faizan | R21: {=_xlfn.BYROW(B65,_xlfn.LAMBDA(_xlpm.party,SUMIFS(ledger!G:G,ledger!B:B,_xlpm.party,ledger!E:E,"<>*RD*")))+_xlfn.IFNA(C100,0)} -> 438975 | S21: {=_xlfn.BYROW(B65, _xlfn.LAMBDA(_xlpm.party, SUMIFS(ledger!G:G, ledger!B:B, _xlpm.party, ledger!E:E, "<>*RD*") / 1.0936 ))+_xlfn.IFNA(D100,0)} -> 401403.62 | T21: {=(_xlfn.BYROW(B65,_xlfn.LAMBDA(_xlpm.party,SUMIFS(ledger!G:G,ledger!B:B,_xlpm.party,ledger!E:E,"<>*RD*",ledger!D:D,"Chamki")+SUMIFS(ledger!G:G, ledger!B:B, _xlpm.party, ledger!E:E, "<>*RD*", ledger!D:D, "Crinkle")))/1.0936)+_xlfn.IFNA(E100,0)} -> 0 | U21: {=(_xlfn.BYROW(B65,_xlfn.LAMBDA(_xlpm.party,SUMIFS(ledger!G:G,ledger!B:B,_xlpm.party,ledger!E:E,"<>*RD*",ledger!D:D,"Silky")))/1.0936)+_xlfn.IFNA(F100,0)} -> 398433.61 | V21: {=(_xlfn.BYROW(B65,_xlfn.LAMBDA(_xlpm.party, (SUMIFS(ledger!J:J,ledger!B:B,_xlpm.party,ledger!E:E,"<>*RD*",ledger!D:D,"Chamki",ledger!C:C,"<>October Closing CF")+ SUMIFS(ledger!J:J,ledger!B:B,_xlpm.party,ledger!E:E,"<>*RD*",ledger!D:D,"Crinkle",ledger!C:C,"<>October Closing CF") )+_xlfn.IFNA(G100,0))))} -> 0 | W21: {=_xlfn.BYROW(B65, _xlfn.LAMBDA(_xlpm.party, SUMIFS(ledger!J:J, ledger!B:B, _xlpm.party, ledger!E:E, "<>*RD*", ledger!D:D, "Silky", ledger!C:C, "<>October Closing CF") )) + _xlfn.IFNA(H100, 0)} -> 5179637 | X21: {=_xlfn.BYROW(B65, _xlfn.LAMBDA(_xlpm.party, SUMIFS(ledger!J:J, ledger!B:B, _xlpm.party, ledger!E:E, "<>*RD*", ledger!D:D, "Slub", ledger!C:C, "<>October Closing CF") ))+ _xlfn.IFNA(I100, 0)} -> 44550.11 | Y21: {=_xlfn.BYROW(B65, _xlfn.LAMBDA(_xlpm.party, SUMIFS(ledger!J:J, ledger!B:B, _xlpm.party, ledger!E:E, "<>*RD*", ledger!D:D, "Satin", ledger!C:C, "<>October Closing CF") ))+ _xlfn.IFNA(J100, 0)} -> 0 | Z21: {=_xlfn.BYROW(B65, _xlfn.LAMBDA(_xlpm.party, SUMIFS(ledger!J:J, ledger!B:B, _xlpm.party, ledger!E:E, "<>*RD*", ledger!D:D, "Black-Chamki", ledger!C:C, "<>October Closing CF") ))} -> 0 | AA21: {=_xlfn.BYROW(B65, _xlfn.LAMBDA(_xlpm.party, SUMIFS(ledger!J:J, ledger!B:B, _xlpm.party, ledger!E:E, "<>*RD*", ledger!D:D, "Kataan", ledger!C:C, "<>October Closing CF") ))} -> 0 | AB21: =V21+W21+X21+Y21+Z21+AA21 -> 5224187.1 | AC21: =(SUMIF(Table14[Party],Q21,Table14[Credit]))+_xlfn.IFNA(L100,0) -> 4915571 | AD21: =AB21-AC21 -> 308616.09 | AE21: 10 | AF21: 13
Q22: Shafique Ansari | R22: {=_xlfn.BYROW(B66,_xlfn.LAMBDA(_xlpm.party,SUMIFS(ledger!G:G,ledger!B:B,_xlpm.party,ledger!E:E,"<>*RD*")))+_xlfn.IFNA(C101,0)} -> 82290 | S22: {=_xlfn.BYROW(B66, _xlfn.LAMBDA(_xlpm.party, SUMIFS(ledger!G:G, ledger!B:B, _xlpm.party, ledger!E:E, "<>*RD*") / 1.0936 ))+_xlfn.IFNA(D101,0)} -> 75246.891 | T22: {=(_xlfn.BYROW(B66,_xlfn.LAMBDA(_xlpm.party,SUMIFS(ledger!G:G,ledger!B:B,_xlpm.party,ledger!E:E,"<>*RD*",ledger!D:D,"Chamki")+SUMIFS(ledger!G:G, ledger!B:B, _xlpm.party, ledger!E:E, "<>*RD*", ledger!D:D, "Crinkle")))/1.0936)+_xlfn.IFNA(E101,0)} -> 64300.475 | U22: {=(_xlfn.BYROW(B66,_xlfn.LAMBDA(_xlpm.party,SUMIFS(ledger!G:G,ledger!B:B,_xlpm.party,ledger!E:E,"<>*RD*",ledger!D:D,"Silky")))/1.0936)+_xlfn.IFNA(F101,0)} -> 7565.8376 | V22: {=(_xlfn.BYROW(B66,_xlfn.LAMBDA(_xlpm.party, (SUMIFS(ledger!J:J,ledger!B:B,_xlpm.party,ledger!E:E,"<>*RD*",ledger!D:D,"Chamki",ledger!C:C,"<>October Closing CF")+ SUMIFS(ledger!J:J,ledger!B:B,_xlpm.party,ledger!E:E,"<>*RD*",ledger!D:D,"Crinkle",ledger!C:C,"<>October Closing CF") )+_xlfn.IFNA(G101,0))))} -> 643004.75 | W22: {=_xlfn.BYROW(B66, _xlfn.LAMBDA(_xlpm.party, SUMIFS(ledger!J:J, ledger!B:B, _xlpm.party, ledger!E:E, "<>*RD*", ledger!D:D, "Silky", ledger!C:C, "<>October Closing CF") )) + _xlfn.IFNA(H101, 0)} -> 98355.889 | X22: {=_xlfn.BYROW(B66, _xlfn.LAMBDA(_xlpm.party, SUMIFS(ledger!J:J, ledger!B:B, _xlpm.party, ledger!E:E, "<>*RD*", ledger!D:D, "Slub", ledger!C:C, "<>October Closing CF") ))+ _xlfn.IFNA(I101, 0)} -> 0 | Y22: {=_xlfn.BYROW(B66, _xlfn.LAMBDA(_xlpm.party, SUMIFS(ledger!J:J, ledger!B:B, _xlpm.party, ledger!E:E, "<>*RD*", ledger!D:D, "Satin", ledger!C:C, "<>October Closing CF") ))+ _xlfn.IFNA(J101, 0)} -> 94656.181 | Z22: {=_xlfn.BYROW(B66, _xlfn.LAMBDA(_xlpm.party, SUMIFS(ledger!J:J, ledger!B:B, _xlpm.party, ledger!E:E, "<>*RD*", ledger!D:D, "Black-Chamki", ledger!C:C, "<>October Closing CF") ))} -> 0 | AA22: {=_xlfn.BYROW(B66, _xlfn.LAMBDA(_xlpm.party, SUMIFS(ledger!J:J, ledger!B:B, _xlpm.party, ledger!E:E, "<>*RD*", ledger!D:D, "Kataan", ledger!C:C, "<>October Closing CF") ))} -> 0 | AB22: =V22+W22+X22+Y22+Z22+AA22 -> 836016.83 | AC22: =(SUMIF(Table14[Party],Q22,Table14[Credit]))+_xlfn.IFNA(L101,0) -> 835660 | AD22: =AB22-AC22 -> 356.82516 | AE22: 10 | AF22: 13
B23: Total influx | C23: =SUM(K49:K71) -> 17900753 | D23: (considering 10.5) | Q23: Amjad sohail | R23: {=_xlfn.BYROW(B67,_xlfn.LAMBDA(_xlpm.party,SUMIFS(ledger!G:G,ledger!B:B,_xlpm.party,ledger!E:E,"<>*RD*")))+_xlfn.IFNA(C102,0)} -> 281909 | S23: {=_xlfn.BYROW(B67, _xlfn.LAMBDA(_xlpm.party, SUMIFS(ledger!G:G, ledger!B:B, _xlpm.party, ledger!E:E, "<>*RD*") / 1.0936 ))+_xlfn.IFNA(D102,0)} -> 257780.72 | T23: {=(_xlfn.BYROW(B67,_xlfn.LAMBDA(_xlpm.party,SUMIFS(ledger!G:G,ledger!B:B,_xlpm.party,ledger!E:E,"<>*RD*",ledger!D:D,"Chamki")+SUMIFS(ledger!G:G, ledger!B:B, _xlpm.party, ledger!E:E, "<>*RD*", ledger!D:D, "Crinkle")))/1.0936)+_xlfn.IFNA(E102,0)} -> 213946.6 | U23: {=(_xlfn.BYROW(B67,_xlfn.LAMBDA(_xlpm.party,SUMIFS(ledger!G:G,ledger!B:B,_xlpm.party,ledger!E:E,"<>*RD*",ledger!D:D,"Silky")))/1.0936)+_xlfn.IFNA(F102,0)} -> 43834.126 | V23: {=(_xlfn.BYROW(B67,_xlfn.LAMBDA(_xlpm.party, (SUMIFS(ledger!J:J,ledger!B:B,_xlpm.party,ledger!E:E,"<>*RD*",ledger!D:D,"Chamki",ledger!C:C,"<>October Closing CF")+ SUMIFS(ledger!J:J,ledger!B:B,_xlpm.party,ledger!E:E,"<>*RD*",ledger!D:D,"Crinkle",ledger!C:C,"<>October Closing CF") )+_xlfn.IFNA(G102,0))))} -> 2139466 | W23: {=_xlfn.BYROW(B67, _xlfn.LAMBDA(_xlpm.party, SUMIFS(ledger!J:J, ledger!B:B, _xlpm.party, ledger!E:E, "<>*RD*", ledger!D:D, "Silky", ledger!C:C, "<>October Closing CF") )) + _xlfn.IFNA(H102, 0)} -> 569843.64 | X23: {=_xlfn.BYROW(B67, _xlfn.LAMBDA(_xlpm.party, SUMIFS(ledger!J:J, ledger!B:B, _xlpm.party, ledger!E:E, "<>*RD*", ledger!D:D, "Slub", ledger!C:C, "<>October Closing CF") ))+ _xlfn.IFNA(I102, 0)} -> 0 | Y23: {=_xlfn.BYROW(B67, _xlfn.LAMBDA(_xlpm.party, SUMIFS(ledger!J:J, ledger!B:B, _xlpm.party, ledger!E:E, "<>*RD*", ledger!D:D, "Satin", ledger!C:C, "<>October Closing CF") ))+ _xlfn.IFNA(J102, 0)} -> 0 | Z23: {=_xlfn.BYROW(B67, _xlfn.LAMBDA(_xlpm.party, SUMIFS(ledger!J:J, ledger!B:B, _xlpm.party, ledger!E:E, "<>*RD*", ledger!D:D, "Black-Chamki", ledger!C:C, "<>October Closing CF") ))} -> 0 | AA23: {=_xlfn.BYROW(B67, _xlfn.LAMBDA(_xlpm.party, SUMIFS(ledger!J:J, ledger!B:B, _xlpm.party, ledger!E:E, "<>*RD*", ledger!D:D, "Kataan", ledger!C:C, "<>October Closing CF") ))} -> 0 | AB23: =V23+W23+X23+Y23+Z23+AA23 -> 2709309.6 | AC23: =(SUMIF(Table14[Party],Q23,Table14[Credit]))+_xlfn.IFNA(L102,0) -> 2300000 | AD23: =AB23-AC23 -> 409309.62 | AE23: 10 | AF23: 13
Q24: Salman Zaffar | R24: {=_xlfn.BYROW(B68,_xlfn.LAMBDA(_xlpm.party,SUMIFS(ledger!G:G,ledger!B:B,_xlpm.party,ledger!E:E,"<>*RD*")))+_xlfn.IFNA(C103,0)} -> 55541 | S24: {=_xlfn.BYROW(B68, _xlfn.LAMBDA(_xlpm.party, SUMIFS(ledger!G:G, ledger!B:B, _xlpm.party, ledger!E:E, "<>*RD*") / 1.0936 ))+_xlfn.IFNA(D103,0)} -> 50787.308 | T24: {=(_xlfn.BYROW(B68,_xlfn.LAMBDA(_xlpm.party,SUMIFS(ledger!G:G,ledger!B:B,_xlpm.party,ledger!E:E,"<>*RD*",ledger!D:D,"Chamki")+SUMIFS(ledger!G:G, ledger!B:B, _xlpm.party, ledger!E:E, "<>*RD*", ledger!D:D, "Crinkle")))/1.0936)+_xlfn.IFNA(E103,0)} -> 14355.34 | U24: {=(_xlfn.BYROW(B68,_xlfn.LAMBDA(_xlpm.party,SUMIFS(ledger!G:G,ledger!B:B,_xlpm.party,ledger!E:E,"<>*RD*",ledger!D:D,"Silky")))/1.0936)+_xlfn.IFNA(F103,0)} -> 31409.108 | V24: {=(_xlfn.BYROW(B68,_xlfn.LAMBDA(_xlpm.party, (SUMIFS(ledger!J:J,ledger!B:B,_xlpm.party,ledger!E:E,"<>*RD*",ledger!D:D,"Chamki",ledger!C:C,"<>October Closing CF")+ SUMIFS(ledger!J:J,ledger!B:B,_xlpm.party,ledger!E:E,"<>*RD*",ledger!D:D,"Crinkle",ledger!C:C,"<>October Closing CF") )+_xlfn.IFNA(G103,0))))} -> 143553.4 | W24: {=_xlfn.BYROW(B68, _xlfn.LAMBDA(_xlpm.party, SUMIFS(ledger!J:J, ledger!B:B, _xlpm.party, ledger!E:E, "<>*RD*", ledger!D:D, "Silky", ledger!C:C, "<>October Closing CF") )) + _xlfn.IFNA(H103, 0)} -> 408318.4 | X24: {=_xlfn.BYROW(B68, _xlfn.LAMBDA(_xlpm.party, SUMIFS(ledger!J:J, ledger!B:B, _xlpm.party, ledger!E:E, "<>*RD*", ledger!D:D, "Slub", ledger!C:C, "<>October Closing CF") ))+ _xlfn.IFNA(I103, 0)} -> 0 | Y24: {=_xlfn.BYROW(B68, _xlfn.LAMBDA(_xlpm.party, SUMIFS(ledger!J:J, ledger!B:B, _xlpm.party, ledger!E:E, "<>*RD*", ledger!D:D, "Satin", ledger!C:C, "<>October Closing CF") ))+ _xlfn.IFNA(J103, 0)} -> 0 | Z24: {=_xlfn.BYROW(B68, _xlfn.LAMBDA(_xlpm.party, SUMIFS(ledger!J:J, ledger!B:B, _xlpm.party, ledger!E:E, "<>*RD*", ledger!D:D, "Black-Chamki", ledger!C:C, "<>October Closing CF") ))} -> 60274.323 | AA24: {=_xlfn.BYROW(B68, _xlfn.LAMBDA(_xlpm.party, SUMIFS(ledger!J:J, ledger!B:B, _xlpm.party, ledger!E:E, "<>*RD*", ledger!D:D, "Kataan", ledger!C:C, "<>October Closing CF") ))} -> 0 | AB24: =V24+W24+X24+Y24+Z24+AA24 -> 612146.12 | AC24: =(SUMIF(Table14[Party],Q24,Table14[Credit]))+_xlfn.IFNA(L103,0) -> 0 | AD24: =AB24-AC24 -> 612146.12 | AE24: 10 | AF24: 13
Q25: Shahid Qasayi | R25: {=_xlfn.BYROW(B69,_xlfn.LAMBDA(_xlpm.party,SUMIFS(ledger!G:G,ledger!B:B,_xlpm.party,ledger!E:E,"<>*RD*")))+_xlfn.IFNA(C104,0)} -> 165343 | S25: {=_xlfn.BYROW(B69, _xlfn.LAMBDA(_xlpm.party, SUMIFS(ledger!G:G, ledger!B:B, _xlpm.party, ledger!E:E, "<>*RD*") / 1.0936 ))+_xlfn.IFNA(D104,0)} -> 151191.48 | T25: {=(_xlfn.BYROW(B69,_xlfn.LAMBDA(_xlpm.party,SUMIFS(ledger!G:G,ledger!B:B,_xlpm.party,ledger!E:E,"<>*RD*",ledger!D:D,"Chamki")+SUMIFS(ledger!G:G, ledger!B:B, _xlpm.party, ledger!E:E, "<>*RD*", ledger!D:D, "Crinkle")))/1.0936)+_xlfn.IFNA(E104,0)} -> 113495.79 | U25: {=(_xlfn.BYROW(B69,_xlfn.LAMBDA(_xlpm.party,SUMIFS(ledger!G:G,ledger!B:B,_xlpm.party,ledger!E:E,"<>*RD*",ledger!D:D,"Silky")))/1.0936)+_xlfn.IFNA(F104,0)} -> 0 | V25: {=(_xlfn.BYROW(B69,_xlfn.LAMBDA(_xlpm.party, (SUMIFS(ledger!J:J,ledger!B:B,_xlpm.party,ledger!E:E,"<>*RD*",ledger!D:D,"Chamki",ledger!C:C,"<>October Closing CF")+ SUMIFS(ledger!J:J,ledger!B:B,_xlpm.party,ledger!E:E,"<>*RD*",ledger!D:D,"Crinkle",ledger!C:C,"<>October Closing CF") )+_xlfn.IFNA(G104,0))))} -> 1134957.9 | W25: {=_xlfn.BYROW(B69, _xlfn.LAMBDA(_xlpm.party, SUMIFS(ledger!J:J, ledger!B:B, _xlpm.party, ledger!E:E, "<>*RD*", ledger!D:D, "Silky", ledger!C:C, "<>October Closing CF") )) + _xlfn.IFNA(H104, 0)} -> 0 | X25: {=_xlfn.BYROW(B69, _xlfn.LAMBDA(_xlpm.party, SUMIFS(ledger!J:J, ledger!B:B, _xlpm.party, ledger!E:E, "<>*RD*", ledger!D:D, "Slub", ledger!C:C, "<>October Closing CF") ))+ _xlfn.IFNA(I104, 0)} -> 0 | Y25: {=_xlfn.BYROW(B69, _xlfn.LAMBDA(_xlpm.party, SUMIFS(ledger!J:J, ledger!B:B, _xlpm.party, ledger!E:E, "<>*RD*", ledger!D:D, "Satin", ledger!C:C, "<>October Closing CF") ))+ _xlfn.IFNA(J104, 0)} -> 0 | Z25: {=_xlfn.BYROW(B69, _xlfn.LAMBDA(_xlpm.party, SUMIFS(ledger!J:J, ledger!B:B, _xlpm.party, ledger!E:E, "<>*RD*", ledger!D:D, "Black-Chamki", ledger!C:C, "<>October Closing CF") ))} -> 0 | AA25: {=_xlfn.BYROW(B69, _xlfn.LAMBDA(_xlpm.party, SUMIFS(ledger!J:J, ledger!B:B, _xlpm.party, ledger!E:E, "<>*RD*", ledger!D:D, "Kataan", ledger!C:C, "<>October Closing CF") ))} -> 414652.52 | AB25: =V25+W25+X25+Y25+Z25+AA25 -> 1549610.5 | AC25: =(SUMIF(Table14[Party],Q25,Table14[Credit]))+_xlfn.IFNA(L104,0) -> 1103325 | AD25: =AB25-AC25 -> 446285.46 | AE25: 10 | AF25: 13
Q26: Hameed corporation | R26: {=_xlfn.BYROW(B70,_xlfn.LAMBDA(_xlpm.party,SUMIFS(ledger!G:G,ledger!B:B,_xlpm.party,ledger!E:E,"<>*RD*")))+_xlfn.IFNA(C105,0)} -> 46404 | S26: {=_xlfn.BYROW(B70, _xlfn.LAMBDA(_xlpm.party, SUMIFS(ledger!G:G, ledger!B:B, _xlpm.party, ledger!E:E, "<>*RD*") / 1.0936 ))+_xlfn.IFNA(D105,0)} -> 42432.334 | T26: {=(_xlfn.BYROW(B70,_xlfn.LAMBDA(_xlpm.party,SUMIFS(ledger!G:G,ledger!B:B,_xlpm.party,ledger!E:E,"<>*RD*",ledger!D:D,"Chamki")+SUMIFS(ledger!G:G, ledger!B:B, _xlpm.party, ledger!E:E, "<>*RD*", ledger!D:D, "Crinkle")))/1.0936)+_xlfn.IFNA(E105,0)} -> 42432.334 | U26: {=(_xlfn.BYROW(B70,_xlfn.LAMBDA(_xlpm.party,SUMIFS(ledger!G:G,ledger!B:B,_xlpm.party,ledger!E:E,"<>*RD*",ledger!D:D,"Silky")))/1.0936)+_xlfn.IFNA(F105,0)} -> 0 | V26: {=(_xlfn.BYROW(B70,_xlfn.LAMBDA(_xlpm.party, (SUMIFS(ledger!J:J,ledger!B:B,_xlpm.party,ledger!E:E,"<>*RD*",ledger!D:D,"Chamki",ledger!C:C,"<>October Closing CF")+ SUMIFS(ledger!J:J,ledger!B:B,_xlpm.party,ledger!E:E,"<>*RD*",ledger!D:D,"Crinkle",ledger!C:C,"<>October Closing CF") )+_xlfn.IFNA(G105,0))))} -> 424323.34 | W26: {=_xlfn.BYROW(B70, _xlfn.LAMBDA(_xlpm.party, SUMIFS(ledger!J:J, ledger!B:B, _xlpm.party, ledger!E:E, "<>*RD*", ledger!D:D, "Silky", ledger!C:C, "<>October Closing CF") )) + _xlfn.IFNA(H105, 0)} -> 0 | X26: {=_xlfn.BYROW(B70, _xlfn.LAMBDA(_xlpm.party, SUMIFS(ledger!J:J, ledger!B:B, _xlpm.party, ledger!E:E, "<>*RD*", ledger!D:D, "Slub", ledger!C:C, "<>October Closing CF") ))+ _xlfn.IFNA(I105, 0)} -> 0 | Y26: {=_xlfn.BYROW(B70, _xlfn.LAMBDA(_xlpm.party, SUMIFS(ledger!J:J, ledger!B:B, _xlpm.party, ledger!E:E, "<>*RD*", ledger!D:D, "Satin", ledger!C:C, "<>October Closing CF") ))+ _xlfn.IFNA(J105, 0)} -> 0 | Z26: {=_xlfn.BYROW(B70, _xlfn.LAMBDA(_xlpm.party, SUMIFS(ledger!J:J, ledger!B:B, _xlpm.party, ledger!E:E, "<>*RD*", ledger!D:D, "Black-Chamki", ledger!C:C, "<>October Closing CF") ))} -> 0 | AA26: {=_xlfn.BYROW(B70, _xlfn.LAMBDA(_xlpm.party, SUMIFS(ledger!J:J, ledger!B:B, _xlpm.party, ledger!E:E, "<>*RD*", ledger!D:D, "Kataan", ledger!C:C, "<>October Closing CF") ))} -> 0 | AB26: =V26+W26+X26+Y26+Z26+AA26 -> 424323.34 | AC26: =(SUMIF(Table14[Party],Q26,Table14[Credit]))+_xlfn.IFNA(L105,0) -> 424323 | AD26: =AB26-AC26 -> 0.33577176 | AE26: 10 | AF26: 13
Q27: ibraheem behraam | R27: {=_xlfn.BYROW(B71,_xlfn.LAMBDA(_xlpm.party,SUMIFS(ledger!G:G,ledger!B:B,_xlpm.party,ledger!E:E,"<>*RD*")))+_xlfn.IFNA(C106,0)} -> 35948 | S27: {=_xlfn.BYROW(B71, _xlfn.LAMBDA(_xlpm.party, SUMIFS(ledger!G:G, ledger!B:B, _xlpm.party, ledger!E:E, "<>*RD*") / 1.0936 ))+_xlfn.IFNA(D106,0)} -> 32871.251 | T27: {=(_xlfn.BYROW(B71,_xlfn.LAMBDA(_xlpm.party,SUMIFS(ledger!G:G,ledger!B:B,_xlpm.party,ledger!E:E,"<>*RD*",ledger!D:D,"Chamki")+SUMIFS(ledger!G:G, ledger!B:B, _xlpm.party, ledger!E:E, "<>*RD*", ledger!D:D, "Crinkle")))/1.0936)+_xlfn.IFNA(E106,0)} -> 0 | U27: {=(_xlfn.BYROW(B71,_xlfn.LAMBDA(_xlpm.party,SUMIFS(ledger!G:G,ledger!B:B,_xlpm.party,ledger!E:E,"<>*RD*",ledger!D:D,"Silky")))/1.0936)+_xlfn.IFNA(F106,0)} -> 32871.251 | V27: {=(_xlfn.BYROW(B71,_xlfn.LAMBDA(_xlpm.party, (SUMIFS(ledger!J:J,ledger!B:B,_xlpm.party,ledger!E:E,"<>*RD*",ledger!D:D,"Chamki",ledger!C:C,"<>October Closing CF")+ SUMIFS(ledger!J:J,ledger!B:B,_xlpm.party,ledger!E:E,"<>*RD*",ledger!D:D,"Crinkle",ledger!C:C,"<>October Closing CF") )+_xlfn.IFNA(G106,0))))} -> 0 | W27: {=_xlfn.BYROW(B71, _xlfn.LAMBDA(_xlpm.party, SUMIFS(ledger!J:J, ledger!B:B, _xlpm.party, ledger!E:E, "<>*RD*", ledger!D:D, "Silky", ledger!C:C, "<>October Closing CF") )) + _xlfn.IFNA(H106, 0)} -> 427326.26 | X27: {=_xlfn.BYROW(B71, _xlfn.LAMBDA(_xlpm.party, SUMIFS(ledger!J:J, ledger!B:B, _xlpm.party, ledger!E:E, "<>*RD*", ledger!D:D, "Slub", ledger!C:C, "<>October Closing CF") ))+ _xlfn.IFNA(I106, 0)} -> 0 | Y27: {=_xlfn.BYROW(B71, _xlfn.LAMBDA(_xlpm.party, SUMIFS(ledger!J:J, ledger!B:B, _xlpm.party, ledger!E:E, "<>*RD*", ledger!D:D, "Satin", ledger!C:C, "<>October Closing CF") ))+ _xlfn.IFNA(J106, 0)} -> 0 | Z27: {=_xlfn.BYROW(B71, _xlfn.LAMBDA(_xlpm.party, SUMIFS(ledger!J:J, ledger!B:B, _xlpm.party, ledger!E:E, "<>*RD*", ledger!D:D, "Black-Chamki", ledger!C:C, "<>October Closing CF") ))} -> 0 | AA27: {=_xlfn.BYROW(B71, _xlfn.LAMBDA(_xlpm.party, SUMIFS(ledger!J:J, ledger!B:B, _xlpm.party, ledger!E:E, "<>*RD*", ledger!D:D, "Kataan", ledger!C:C, "<>October Closing CF") ))} -> 0 | AB27: =V27+W27+X27+Y27+Z27+AA27 -> 427326.26 | AC27: =(SUMIF(Table14[Party],Q27,Table14[Credit]))+_xlfn.IFNA(L106,0) -> 437000 | AD27: =AB27-AC27 -> -9673.7381 | AE27: 10 | AF27: 13
